<sdf version='1.6'>
  <world name='default'>
    <plugin name='ros_link_attacher_plugin' filename='libgazebo_ros_link_attacher.so'/>
    <light name='sun' type='directional'>
      <cast_shadows>1</cast_shadows>
      <pose frame=''>0 0 10 0 -0 0</pose>
      <diffuse>0.8 0.8 0.8 1</diffuse>
      <specular>0.2 0.2 0.2 1</specular>
      <attenuation>
        <range>1000</range>
        <constant>0.9</constant>
        <linear>0.01</linear>
        <quadratic>0.001</quadratic>
      </attenuation>
      <direction>-0.5 0.1 -0.9</direction>
    </light>
    <model name='ground_plane'>
      <static>1</static>
      <link name='link'>
        <collision name='collision'>
          <geometry>
            <plane>
              <normal>0 0 1</normal>
              <size>100 100</size>
            </plane>
          </geometry>
          <surface>
            <contact>
              <collide_bitmask>65535</collide_bitmask>
              <ode/>
            </contact>
            <friction>
              <ode>
                <mu>100</mu>
                <mu2>50</mu2>
              </ode>
              <torsional>
                <ode/>
              </torsional>
            </friction>
            <bounce/>
          </surface>
          <max_contacts>10</max_contacts>
        </collision>
        <visual name='visual'>
          <cast_shadows>0</cast_shadows>
          <geometry>
            <plane>
              <normal>0 0 1</normal>
              <size>100 100</size>
            </plane>
          </geometry>
          <material>
            <script>
              <uri>file://media/materials/scripts/gazebo.material</uri>
              <name>Gazebo/Grey</name>
            </script>
          </material>
        </visual>
        <self_collide>0</self_collide>
        <enable_wind>0</enable_wind>
        <kinematic>0</kinematic>
      </link>
    </model>
    <gravity>0 0 -9.8</gravity>
    <magnetic_field>6e-06 2.3e-05 -4.2e-05</magnetic_field>
    <atmosphere type='adiabatic'/>
    <physics name='default_physics' default='0' type='ode'>
      <max_step_size>0.001</max_step_size>
      <real_time_factor>1</real_time_factor>
      <real_time_update_rate>1000</real_time_update_rate>
    </physics>
    <scene>
      <ambient>0.4 0.4 0.4 1</ambient>
      <background>0.7 0.7 0.7 1</background>
      <shadows>1</shadows>
    </scene>
    <audio>
      <device>default</device>
    </audio>
    <wind/>
    <spherical_coordinates>
      <surface_model>EARTH_WGS84</surface_model>
      <latitude_deg>0</latitude_deg>
      <longitude_deg>0</longitude_deg>
      <elevation>0</elevation>
      <heading_deg>0</heading_deg>
    </spherical_coordinates>
    <model name='robot'>
      <link name='base_link'>
        <pose frame=''>0 0 0 0 -0 0</pose>
        <inertial>
          <pose frame=''>-0.000267 1.00404 -0.074987 0 -0 0</pose>
          <mass>666.772</mass>
          <inertia>
            <ixx>272.683</ixx>
            <ixy>0.266152</ixy>
            <ixz>-0.0288193</ixz>
            <iyy>77.458</iyy>
            <iyz>0.368223</iyz>
            <izz>346.308</izz>
          </inertia>
        </inertial>
        <collision name='base_link_inertia_collision'>
          <pose frame=''>0 0 0 0 -0 0</pose>
          <geometry>
            <mesh>
              <scale>1 1 1</scale>
              <uri>/home/ur/Desktop/test/UR_Robot_Disassembly/rokae/src/gazebo_link_attacher_ws/src/fmauch_universal_robot/ur_description/meshes/ur10e/collision/base.stl</uri>
            </mesh>
          </geometry>
          <max_contacts>10</max_contacts>
          <surface>
            <contact>
              <ode/>
            </contact>
            <bounce/>
            <friction>
              <torsional>
                <ode/>
              </torsional>
              <ode/>
            </friction>
          </surface>
        </collision>
        <collision name='base_link_fixed_joint_lump__battery_pack_base_link_collision_1'>
          <pose frame=''>0 0 0.002 0 -0 1.5708</pose>
          <geometry>
            <mesh>
              <scale>1 1 1</scale>
              <uri>/home/ur/Desktop/test/UR_Robot_Disassembly/rokae/src/gazebo_link_attacher_ws/src/battery_pack/meshes/battery_pack_base_link.STL</uri>
            </mesh>
          </geometry>
          <max_contacts>10</max_contacts>
          <surface>
            <contact>
              <ode/>
            </contact>
            <bounce/>
            <friction>
              <torsional>
                <ode/>
              </torsional>
              <ode/>
            </friction>
          </surface>
        </collision>
        <collision name='base_link_fixed_joint_lump__M10_1_Link_collision_2'>
          <pose frame=''>0.196 0.5215 0.053 0 -0 1.5708</pose>
          <geometry>
            <mesh>
              <scale>1 1 1</scale>
              <uri>/home/ur/Desktop/test/UR_Robot_Disassembly/rokae/src/gazebo_link_attacher_ws/src/battery_pack/meshes/M10_1_Link.STL</uri>
            </mesh>
          </geometry>
          <max_contacts>10</max_contacts>
          <surface>
            <contact>
              <ode/>
            </contact>
            <bounce/>
            <friction>
              <torsional>
                <ode/>
              </torsional>
              <ode/>
            </friction>
          </surface>
        </collision>
        <collision name='base_link_fixed_joint_lump__M10_2_Link_collision_3'>
          <pose frame=''>0.296 0.5215 0.053 0 -0 1.5708</pose>
          <geometry>
            <mesh>
              <scale>1 1 1</scale>
              <uri>/home/ur/Desktop/test/UR_Robot_Disassembly/rokae/src/gazebo_link_attacher_ws/src/battery_pack/meshes/M10_2_Link.STL</uri>
            </mesh>
          </geometry>
          <max_contacts>10</max_contacts>
          <surface>
            <contact>
              <ode/>
            </contact>
            <bounce/>
            <friction>
              <torsional>
                <ode/>
              </torsional>
              <ode/>
            </friction>
          </surface>
        </collision>
        <collision name='base_link_fixed_joint_lump__M10_3_Link_collision_4'>
          <pose frame=''>0.396 0.5215 0.053 0 -0 1.5708</pose>
          <geometry>
            <mesh>
              <scale>1 1 1</scale>
              <uri>/home/ur/Desktop/test/UR_Robot_Disassembly/rokae/src/gazebo_link_attacher_ws/src/battery_pack/meshes/M10_3_Link.STL</uri>
            </mesh>
          </geometry>
          <max_contacts>10</max_contacts>
          <surface>
            <contact>
              <ode/>
            </contact>
            <bounce/>
            <friction>
              <torsional>
                <ode/>
              </torsional>
              <ode/>
            </friction>
          </surface>
        </collision>
        <collision name='base_link_fixed_joint_lump__M6_1_Link_collision_5'>
          <pose frame=''>-0.404 0.5215 0.053 0 -0 1.5708</pose>
          <geometry>
            <mesh>
              <scale>1 1 1</scale>
              <uri>/home/ur/Desktop/test/UR_Robot_Disassembly/rokae/src/gazebo_link_attacher_ws/src/battery_pack/meshes/M6_1_Link.STL</uri>
            </mesh>
          </geometry>
          <max_contacts>10</max_contacts>
          <surface>
            <contact>
              <ode/>
            </contact>
            <bounce/>
            <friction>
              <torsional>
                <ode/>
              </torsional>
              <ode/>
            </friction>
          </surface>
        </collision>
        <collision name='base_link_fixed_joint_lump__M6_2_Link_collision_6'>
          <pose frame=''>-0.304 0.5215 0.053 0 -0 1.5708</pose>
          <geometry>
            <mesh>
              <scale>1 1 1</scale>
              <uri>/home/ur/Desktop/test/UR_Robot_Disassembly/rokae/src/gazebo_link_attacher_ws/src/battery_pack/meshes/M6_2_Link.STL</uri>
            </mesh>
          </geometry>
          <max_contacts>10</max_contacts>
          <surface>
            <contact>
              <ode/>
            </contact>
            <bounce/>
            <friction>
              <torsional>
                <ode/>
              </torsional>
              <ode/>
            </friction>
          </surface>
        </collision>
        <collision name='base_link_fixed_joint_lump__M6_3_Link_collision_7'>
          <pose frame=''>-0.204 0.5215 0.053 0 -0 1.5708</pose>
          <geometry>
            <mesh>
              <scale>1 1 1</scale>
              <uri>/home/ur/Desktop/test/UR_Robot_Disassembly/rokae/src/gazebo_link_attacher_ws/src/battery_pack/meshes/M6_3_Link.STL</uri>
            </mesh>
          </geometry>
          <max_contacts>10</max_contacts>
          <surface>
            <contact>
              <ode/>
            </contact>
            <bounce/>
            <friction>
              <torsional>
                <ode/>
              </torsional>
              <ode/>
            </friction>
          </surface>
        </collision>
        <collision name='base_link_fixed_joint_lump__M8_1_Link_collision_8'>
          <pose frame=''>-0.104 0.5215 0.053 0 -0 1.5708</pose>
          <geometry>
            <mesh>
              <scale>1 1 1</scale>
              <uri>/home/ur/Desktop/test/UR_Robot_Disassembly/rokae/src/gazebo_link_attacher_ws/src/battery_pack/meshes/M8_1_Link.STL</uri>
            </mesh>
          </geometry>
          <max_contacts>10</max_contacts>
          <surface>
            <contact>
              <ode/>
            </contact>
            <bounce/>
            <friction>
              <torsional>
                <ode/>
              </torsional>
              <ode/>
            </friction>
          </surface>
        </collision>
        <collision name='base_link_fixed_joint_lump__M8_2_Link_collision_9'>
          <pose frame=''>-0.004 0.5215 0.053 0 -0 1.5708</pose>
          <geometry>
            <mesh>
              <scale>1 1 1</scale>
              <uri>/home/ur/Desktop/test/UR_Robot_Disassembly/rokae/src/gazebo_link_attacher_ws/src/battery_pack/meshes/M8_2_Link.STL</uri>
            </mesh>
          </geometry>
          <max_contacts>10</max_contacts>
          <surface>
            <contact>
              <ode/>
            </contact>
            <bounce/>
            <friction>
              <torsional>
                <ode/>
              </torsional>
              <ode/>
            </friction>
          </surface>
        </collision>
        <collision name='base_link_fixed_joint_lump__M8_3_Link_collision_10'>
          <pose frame=''>0.096 0.5215 0.053 0 -0 1.5708</pose>
          <geometry>
            <mesh>
              <scale>1 1 1</scale>
              <uri>/home/ur/Desktop/test/UR_Robot_Disassembly/rokae/src/gazebo_link_attacher_ws/src/battery_pack/meshes/M8_3_Link.STL</uri>
            </mesh>
          </geometry>
          <max_contacts>10</max_contacts>
          <surface>
            <contact>
              <ode/>
            </contact>
            <bounce/>
            <friction>
              <torsional>
                <ode/>
              </torsional>
              <ode/>
            </friction>
          </surface>
        </collision>
        <collision name='base_link_fixed_joint_lump__sleeve_plate_Link_collision_11'>
          <pose frame=''>0.45 -0 0.067 0 -0 1.5708</pose>
          <geometry>
            <mesh>
              <scale>1 1 1</scale>
              <uri>/home/ur/Desktop/test/UR_Robot_Disassembly/rokae/src/gazebo_link_attacher_ws/src/battery_pack/meshes/sleeve_plate_Link.STL</uri>
            </mesh>
          </geometry>
          <max_contacts>10</max_contacts>
          <surface>
            <contact>
              <ode/>
            </contact>
            <bounce/>
            <friction>
              <torsional>
                <ode/>
              </torsional>
              <ode/>
            </friction>
          </surface>
        </collision>
        <visual name='base_link_inertia_visual'>
          <pose frame=''>0 0 0 0 -0 0</pose>
          <geometry>
            <mesh>
              <scale>1 1 1</scale>
              <uri>/home/ur/Desktop/test/UR_Robot_Disassembly/rokae/src/gazebo_link_attacher_ws/src/fmauch_universal_robot/ur_description/meshes/ur10e/visual/base.dae</uri>
            </mesh>
          </geometry>
        </visual>
        <visual name='base_link_fixed_joint_lump__battery_pack_base_link_visual_1'>
          <pose frame=''>0 0 0.002 0 -0 1.5708</pose>
          <geometry>
            <mesh>
              <scale>1 1 1</scale>
              <uri>/home/ur/Desktop/test/UR_Robot_Disassembly/rokae/src/gazebo_link_attacher_ws/src/battery_pack/meshes/battery_pack_base_link.STL</uri>
            </mesh>
          </geometry>
        </visual>
        <visual name='base_link_fixed_joint_lump__M10_1_Link_visual_2'>
          <pose frame=''>0.196 0.5215 0.053 0 -0 1.5708</pose>
          <geometry>
            <mesh>
              <scale>1 1 1</scale>
              <uri>/home/ur/Desktop/test/UR_Robot_Disassembly/rokae/src/gazebo_link_attacher_ws/src/battery_pack/meshes/M10_1_Link.STL</uri>
            </mesh>
          </geometry>
        </visual>
        <visual name='base_link_fixed_joint_lump__M10_2_Link_visual_3'>
          <pose frame=''>0.296 0.5215 0.053 0 -0 1.5708</pose>
          <geometry>
            <mesh>
              <scale>1 1 1</scale>
              <uri>/home/ur/Desktop/test/UR_Robot_Disassembly/rokae/src/gazebo_link_attacher_ws/src/battery_pack/meshes/M10_2_Link.STL</uri>
            </mesh>
          </geometry>
        </visual>
        <visual name='base_link_fixed_joint_lump__M10_3_Link_visual_4'>
          <pose frame=''>0.396 0.5215 0.053 0 -0 1.5708</pose>
          <geometry>
            <mesh>
              <scale>1 1 1</scale>
              <uri>/home/ur/Desktop/test/UR_Robot_Disassembly/rokae/src/gazebo_link_attacher_ws/src/battery_pack/meshes/M10_3_Link.STL</uri>
            </mesh>
          </geometry>
        </visual>
        <visual name='base_link_fixed_joint_lump__M6_1_Link_visual_5'>
          <pose frame=''>-0.404 0.5215 0.053 0 -0 1.5708</pose>
          <geometry>
            <mesh>
              <scale>1 1 1</scale>
              <uri>/home/ur/Desktop/test/UR_Robot_Disassembly/rokae/src/gazebo_link_attacher_ws/src/battery_pack/meshes/M6_1_Link.STL</uri>
            </mesh>
          </geometry>
        </visual>
        <visual name='base_link_fixed_joint_lump__M6_2_Link_visual_6'>
          <pose frame=''>-0.304 0.5215 0.053 0 -0 1.5708</pose>
          <geometry>
            <mesh>
              <scale>1 1 1</scale>
              <uri>/home/ur/Desktop/test/UR_Robot_Disassembly/rokae/src/gazebo_link_attacher_ws/src/battery_pack/meshes/M6_2_Link.STL</uri>
            </mesh>
          </geometry>
        </visual>
        <visual name='base_link_fixed_joint_lump__M6_3_Link_visual_7'>
          <pose frame=''>-0.204 0.5215 0.053 0 -0 1.5708</pose>
          <geometry>
            <mesh>
              <scale>1 1 1</scale>
              <uri>/home/ur/Desktop/test/UR_Robot_Disassembly/rokae/src/gazebo_link_attacher_ws/src/battery_pack/meshes/M6_3_Link.STL</uri>
            </mesh>
          </geometry>
        </visual>
        <visual name='base_link_fixed_joint_lump__M8_1_Link_visual_8'>
          <pose frame=''>-0.104 0.5215 0.053 0 -0 1.5708</pose>
          <geometry>
            <mesh>
              <scale>1 1 1</scale>
              <uri>/home/ur/Desktop/test/UR_Robot_Disassembly/rokae/src/gazebo_link_attacher_ws/src/battery_pack/meshes/M8_1_Link.STL</uri>
            </mesh>
          </geometry>
        </visual>
        <visual name='base_link_fixed_joint_lump__M8_2_Link_visual_9'>
          <pose frame=''>-0.004 0.5215 0.053 0 -0 1.5708</pose>
          <geometry>
            <mesh>
              <scale>1 1 1</scale>
              <uri>/home/ur/Desktop/test/UR_Robot_Disassembly/rokae/src/gazebo_link_attacher_ws/src/battery_pack/meshes/M8_2_Link.STL</uri>
            </mesh>
          </geometry>
        </visual>
        <visual name='base_link_fixed_joint_lump__M8_3_Link_visual_10'>
          <pose frame=''>0.096 0.5215 0.053 0 -0 1.5708</pose>
          <geometry>
            <mesh>
              <scale>1 1 1</scale>
              <uri>/home/ur/Desktop/test/UR_Robot_Disassembly/rokae/src/gazebo_link_attacher_ws/src/battery_pack/meshes/M8_3_Link.STL</uri>
            </mesh>
          </geometry>
        </visual>
        <visual name='base_link_fixed_joint_lump__sleeve_plate_Link_visual_11'>
          <pose frame=''>0.45 -0 0.067 0 -0 1.5708</pose>
          <geometry>
            <mesh>
              <scale>1 1 1</scale>
              <uri>/home/ur/Desktop/test/UR_Robot_Disassembly/rokae/src/gazebo_link_attacher_ws/src/battery_pack/meshes/sleeve_plate_Link.STL</uri>
            </mesh>
          </geometry>
        </visual>
        <self_collide>0</self_collide>
        <enable_wind>0</enable_wind>
        <kinematic>0</kinematic>
      </link>
      <joint name='world_joint' type='fixed'>
        <child>base_link</child>
        <parent>world</parent>
      </joint>
      <link name='shoulder_link'>
        <pose frame=''>0 0 0.1807 0 -0 -3.14159</pose>
        <inertial>
          <pose frame=''>0 0 0 0 -0 0</pose>
          <mass>7.778</mass>
          <inertia>
            <ixx>0.0314743</ixx>
            <ixy>0</ixy>
            <ixz>0</ixz>
            <iyy>0.0314743</iyy>
            <iyz>0</iyz>
            <izz>0.0218756</izz>
          </inertia>
        </inertial>
        <collision name='shoulder_link_collision'>
          <pose frame=''>0 0 0 0 -0 -3.14159</pose>
          <geometry>
            <mesh>
              <scale>1 1 1</scale>
              <uri>/home/ur/Desktop/test/UR_Robot_Disassembly/rokae/src/gazebo_link_attacher_ws/src/fmauch_universal_robot/ur_description/meshes/ur10e/collision/shoulder.stl</uri>
            </mesh>
          </geometry>
          <surface>
            <contact>
              <ode/>
            </contact>
            <friction>
              <ode/>
              <torsional>
                <ode/>
              </torsional>
            </friction>
            <bounce/>
          </surface>
          <max_contacts>10</max_contacts>
        </collision>
        <visual name='shoulder_link_visual'>
          <pose frame=''>0 0 0 0 -0 -3.14159</pose>
          <geometry>
            <mesh>
              <scale>1 1 1</scale>
              <uri>/home/ur/Desktop/test/UR_Robot_Disassembly/rokae/src/gazebo_link_attacher_ws/src/fmauch_universal_robot/ur_description/meshes/ur10e/visual/shoulder.dae</uri>
            </mesh>
          </geometry>
          <material>
            <script>
              <uri>__default__</uri>
              <name>__default__</name>
            </script>
          </material>
        </visual>
        <gravity>1</gravity>
        <velocity_decay/>
        <self_collide>1</self_collide>
        <enable_wind>0</enable_wind>
        <kinematic>0</kinematic>
      </link>
      <joint name='shoulder_pan_joint' type='revolute'>
        <child>shoulder_link</child>
        <parent>base_link</parent>
        <axis>
          <xyz>0 0 1</xyz>
          <limit>
            <lower>-6.28319</lower>
            <upper>6.28319</upper>
            <effort>330</effort>
            <velocity>2.0944</velocity>
          </limit>
          <dynamics>
            <damping>0</damping>
            <friction>0</friction>
            <spring_reference>0</spring_reference>
            <spring_stiffness>0</spring_stiffness>
          </dynamics>
          <use_parent_model_frame>1</use_parent_model_frame>
        </axis>
      </joint>
      <link name='upper_arm_link'>
        <pose frame=''>0 0 0.1807 1.5708 -0 -3.14159</pose>
        <inertial>
          <pose frame=''>-0.306 0 0.175 3.14159 1.57079 3.14159</pose>
          <mass>12.93</mass>
          <inertia>
            <ixx>0.421754</ixx>
            <ixy>0</ixy>
            <ixz>0</ixz>
            <iyy>0.421754</iyy>
            <iyz>0</iyz>
            <izz>0.0363656</izz>
          </inertia>
        </inertial>
        <collision name='upper_arm_link_collision'>
          <pose frame=''>0 0 0.1762 1.5708 0 -1.5708</pose>
          <geometry>
            <mesh>
              <scale>1 1 1</scale>
              <uri>/home/ur/Desktop/test/UR_Robot_Disassembly/rokae/src/gazebo_link_attacher_ws/src/fmauch_universal_robot/ur_description/meshes/ur10e/collision/upperarm.stl</uri>
            </mesh>
          </geometry>
          <surface>
            <contact>
              <ode/>
            </contact>
            <friction>
              <ode/>
              <torsional>
                <ode/>
              </torsional>
            </friction>
            <bounce/>
          </surface>
          <max_contacts>10</max_contacts>
        </collision>
        <visual name='upper_arm_link_visual'>
          <pose frame=''>0 0 0.1762 1.5708 0 -1.5708</pose>
          <geometry>
            <mesh>
              <scale>1 1 1</scale>
              <uri>/home/ur/Desktop/test/UR_Robot_Disassembly/rokae/src/gazebo_link_attacher_ws/src/fmauch_universal_robot/ur_description/meshes/ur10e/visual/upperarm.dae</uri>
            </mesh>
          </geometry>
          <material>
            <script>
              <uri>__default__</uri>
              <name>__default__</name>
            </script>
          </material>
        </visual>
        <gravity>1</gravity>
        <velocity_decay/>
        <self_collide>1</self_collide>
        <enable_wind>0</enable_wind>
        <kinematic>0</kinematic>
      </link>
      <joint name='shoulder_lift_joint' type='revolute'>
        <child>upper_arm_link</child>
        <parent>shoulder_link</parent>
        <axis>
          <xyz>-0 1 -0</xyz>
          <limit>
            <lower>-6.28319</lower>
            <upper>6.28319</upper>
            <effort>330</effort>
            <velocity>2.0944</velocity>
          </limit>
          <dynamics>
            <damping>0</damping>
            <friction>0</friction>
            <spring_reference>0</spring_reference>
            <spring_stiffness>0</spring_stiffness>
          </dynamics>
          <use_parent_model_frame>1</use_parent_model_frame>
        </axis>
      </joint>
      <link name='forearm_link'>
        <pose frame=''>0.6127 0 0.1807 1.5708 -0 -3.14159</pose>
        <inertial>
          <pose frame=''>-0.285775 0 0.0393 3.14159 1.57079 3.14159</pose>
          <mass>3.87</mass>
          <inertia>
            <ixx>0.110793</ixx>
            <ixy>0</ixy>
            <ixz>0</ixz>
            <iyy>0.110793</iyy>
            <iyz>0</iyz>
            <izz>0.0108844</izz>
          </inertia>
        </inertial>
        <collision name='forearm_link_collision'>
          <pose frame=''>0 0 0.0393 1.5708 0 -1.5708</pose>
          <geometry>
            <mesh>
              <scale>1 1 1</scale>
              <uri>/home/ur/Desktop/test/UR_Robot_Disassembly/rokae/src/gazebo_link_attacher_ws/src/fmauch_universal_robot/ur_description/meshes/ur10e/collision/forearm.stl</uri>
            </mesh>
          </geometry>
          <surface>
            <contact>
              <ode/>
            </contact>
            <friction>
              <ode/>
              <torsional>
                <ode/>
              </torsional>
            </friction>
            <bounce/>
          </surface>
          <max_contacts>10</max_contacts>
        </collision>
        <visual name='forearm_link_visual'>
          <pose frame=''>0 0 0.0393 1.5708 0 -1.5708</pose>
          <geometry>
            <mesh>
              <scale>1 1 1</scale>
              <uri>/home/ur/Desktop/test/UR_Robot_Disassembly/rokae/src/gazebo_link_attacher_ws/src/fmauch_universal_robot/ur_description/meshes/ur10e/visual/forearm.dae</uri>
            </mesh>
          </geometry>
          <material>
            <script>
              <uri>__default__</uri>
              <name>__default__</name>
            </script>
          </material>
        </visual>
        <gravity>1</gravity>
        <velocity_decay/>
        <self_collide>1</self_collide>
        <enable_wind>0</enable_wind>
        <kinematic>0</kinematic>
      </link>
      <joint name='elbow_joint' type='revolute'>
        <child>forearm_link</child>
        <parent>upper_arm_link</parent>
        <axis>
          <xyz>-0 1 -0</xyz>
          <limit>
            <lower>-3.14159</lower>
            <upper>3.14159</upper>
            <effort>150</effort>
            <velocity>3.14159</velocity>
          </limit>
          <dynamics>
            <damping>0</damping>
            <friction>0</friction>
            <spring_reference>0</spring_reference>
            <spring_stiffness>0</spring_stiffness>
          </dynamics>
          <use_parent_model_frame>1</use_parent_model_frame>
        </axis>
      </joint>
      <link name='wrist_1_link'>
        <pose frame=''>1.18425 0.17415 0.1807 1.5708 -0 -3.14159</pose>
        <inertial>
          <pose frame=''>0 0 0 0 -0 0</pose>
          <mass>1.96</mass>
          <inertia>
            <ixx>0.00510825</ixx>
            <ixy>0</ixy>
            <ixz>0</ixz>
            <iyy>0.00510825</iyy>
            <iyz>0</iyz>
            <izz>0.0055125</izz>
          </inertia>
        </inertial>
        <collision name='wrist_1_link_collision'>
          <pose frame=''>0 0 -0.135 1.5708 -0 0</pose>
          <geometry>
            <mesh>
              <scale>1 1 1</scale>
              <uri>/home/ur/Desktop/test/UR_Robot_Disassembly/rokae/src/gazebo_link_attacher_ws/src/fmauch_universal_robot/ur_description/meshes/ur10e/collision/wrist1.stl</uri>
            </mesh>
          </geometry>
          <surface>
            <contact>
              <ode/>
            </contact>
            <friction>
              <ode/>
              <torsional>
                <ode/>
              </torsional>
            </friction>
            <bounce/>
          </surface>
          <max_contacts>10</max_contacts>
        </collision>
        <visual name='wrist_1_link_visual'>
          <pose frame=''>0 0 -0.135 1.5708 -0 0</pose>
          <geometry>
            <mesh>
              <scale>1 1 1</scale>
              <uri>/home/ur/Desktop/test/UR_Robot_Disassembly/rokae/src/gazebo_link_attacher_ws/src/fmauch_universal_robot/ur_description/meshes/ur10e/visual/wrist1.dae</uri>
            </mesh>
          </geometry>
          <material>
            <script>
              <uri>__default__</uri>
              <name>__default__</name>
            </script>
          </material>
        </visual>
        <gravity>1</gravity>
        <velocity_decay/>
        <self_collide>1</self_collide>
        <enable_wind>0</enable_wind>
        <kinematic>0</kinematic>
      </link>
      <joint name='wrist_1_joint' type='revolute'>
        <child>wrist_1_link</child>
        <parent>forearm_link</parent>
        <axis>
          <xyz>-0 1 -0</xyz>
          <limit>
            <lower>-6.28319</lower>
            <upper>6.28319</upper>
            <effort>56</effort>
            <velocity>3.14159</velocity>
          </limit>
          <dynamics>
            <damping>0</damping>
            <friction>0</friction>
            <spring_reference>0</spring_reference>
            <spring_stiffness>0</spring_stiffness>
          </dynamics>
          <use_parent_model_frame>1</use_parent_model_frame>
        </axis>
      </joint>
      <link name='wrist_2_link'>
        <pose frame=''>1.18425 0.17415 0.06085 -3.14159 -0 -3.14159</pose>
        <inertial>
          <pose frame=''>0 0 0 0 -0 0</pose>
          <mass>1.96</mass>
          <inertia>
            <ixx>0.00510825</ixx>
            <ixy>0</ixy>
            <ixz>0</ixz>
            <iyy>0.00510825</iyy>
            <iyz>0</iyz>
            <izz>0.0055125</izz>
          </inertia>
        </inertial>
        <collision name='wrist_2_link_collision'>
          <pose frame=''>0 0 -0.12 0 -0 0</pose>
          <geometry>
            <mesh>
              <scale>1 1 1</scale>
              <uri>/home/ur/Desktop/test/UR_Robot_Disassembly/rokae/src/gazebo_link_attacher_ws/src/fmauch_universal_robot/ur_description/meshes/ur10e/collision/wrist2.stl</uri>
            </mesh>
          </geometry>
          <surface>
            <contact>
              <ode/>
            </contact>
            <friction>
              <ode/>
              <torsional>
                <ode/>
              </torsional>
            </friction>
            <bounce/>
          </surface>
          <max_contacts>10</max_contacts>
        </collision>
        <visual name='wrist_2_link_visual'>
          <pose frame=''>0 0 -0.12 0 -0 0</pose>
          <geometry>
            <mesh>
              <scale>1 1 1</scale>
              <uri>/home/ur/Desktop/test/UR_Robot_Disassembly/rokae/src/gazebo_link_attacher_ws/src/fmauch_universal_robot/ur_description/meshes/ur10e/visual/wrist2.dae</uri>
            </mesh>
          </geometry>
          <material>
            <script>
              <uri>__default__</uri>
              <name>__default__</name>
            </script>
          </material>
        </visual>
        <gravity>1</gravity>
        <velocity_decay/>
        <self_collide>1</self_collide>
        <enable_wind>0</enable_wind>
        <kinematic>0</kinematic>
      </link>
      <joint name='wrist_2_joint' type='revolute'>
        <child>wrist_2_link</child>
        <parent>wrist_1_link</parent>
        <axis>
          <xyz>0 -0 -1</xyz>
          <limit>
            <lower>-6.28319</lower>
            <upper>6.28319</upper>
            <effort>56</effort>
            <velocity>3.14159</velocity>
          </limit>
          <dynamics>
            <damping>0</damping>
            <friction>0</friction>
            <spring_reference>0</spring_reference>
            <spring_stiffness>0</spring_stiffness>
          </dynamics>
          <use_parent_model_frame>1</use_parent_model_frame>
        </axis>
      </joint>
      <link name='wrist_3_link'>
        <pose frame=''>1.18425 0.2907 0.06085 1.5708 -0 -3.14159</pose>
        <inertial>
          <pose frame=''>-0.005818 0.001319 0.078947 0 -0 0</pose>
          <mass>0.973092</mass>
          <inertia>
            <ixx>0.00403616</ixx>
            <ixy>-1.58452e-05</ixy>
            <ixz>-0.000428451</ixz>
            <iyy>0.00704559</iyy>
            <iyz>-4.95701e-05</iyz>
            <izz>0.00349662</izz>
          </inertia>
        </inertial>
        <collision name='wrist_3_link_collision'>
          <pose frame=''>0 0 -0.1168 1.5708 -0 0</pose>
          <geometry>
            <mesh>
              <scale>1 1 1</scale>
              <uri>/home/ur/Desktop/test/UR_Robot_Disassembly/rokae/src/gazebo_link_attacher_ws/src/fmauch_universal_robot/ur_description/meshes/ur10e/collision/wrist3.stl</uri>
            </mesh>
          </geometry>
          <surface>
            <contact>
              <ode/>
            </contact>
            <friction>
              <ode/>
              <torsional>
                <ode/>
              </torsional>
            </friction>
            <bounce/>
          </surface>
          <max_contacts>10</max_contacts>
        </collision>
        <collision name='wrist_3_link_fixed_joint_lump__endeffector_base_link_collision_1'>
          <pose frame=''>-0 0 0.002 0 0 -3.14159</pose>
          <geometry>
            <mesh>
              <scale>1 1 1</scale>
              <uri>/home/ur/Desktop/test/UR_Robot_Disassembly/rokae/src/gazebo_link_attacher_ws/src/endeffector/meshes/endeffector_base_link.STL</uri>
            </mesh>
          </geometry>
          <max_contacts>10</max_contacts>
          <surface>
            <contact>
              <ode/>
            </contact>
            <bounce/>
            <friction>
              <torsional>
                <ode/>
              </torsional>
              <ode/>
            </friction>
          </surface>
        </collision>
        <collision name='wrist_3_link_fixed_joint_lump__camera_Link_collision_2'>
          <pose frame=''>-0.18055 0.000297 0.073047 0.000188 -0.10472 -3.14159</pose>
          <geometry>
            <mesh>
              <scale>1 1 1</scale>
              <uri>/home/ur/Desktop/test/UR_Robot_Disassembly/rokae/src/gazebo_link_attacher_ws/src/endeffector/meshes/camera_Link.STL</uri>
            </mesh>
          </geometry>
          <surface>
            <contact>
              <ode/>
            </contact>
            <friction>
              <ode/>
              <torsional>
                <ode/>
              </torsional>
            </friction>
            <bounce/>
          </surface>
          <max_contacts>10</max_contacts>
        </collision>
        <visual name='wrist_3_link_visual'>
          <pose frame=''>0 0 -0.1168 1.5708 -0 0</pose>
          <geometry>
            <mesh>
              <scale>1 1 1</scale>
              <uri>/home/ur/Desktop/test/UR_Robot_Disassembly/rokae/src/gazebo_link_attacher_ws/src/fmauch_universal_robot/ur_description/meshes/ur10e/visual/wrist3.dae</uri>
            </mesh>
          </geometry>
          <material>
            <script>
              <uri>__default__</uri>
              <name>__default__</name>
            </script>
          </material>
        </visual>
        <visual name='wrist_3_link_fixed_joint_lump__endeffector_base_link_visual_1'>
          <pose frame=''>-0 0 0.002 0 0 -3.14159</pose>
          <geometry>
            <mesh>
              <scale>1 1 1</scale>
              <uri>/home/ur/Desktop/test/UR_Robot_Disassembly/rokae/src/gazebo_link_attacher_ws/src/endeffector/meshes/endeffector_base_link.STL</uri>
            </mesh>
          </geometry>
        </visual>
        <visual name='wrist_3_link_fixed_joint_lump__camera_Link_visual_2'>
          <pose frame=''>-0.18055 0.000297 0.073047 0.000188 -0.10472 -3.14159</pose>
          <geometry>
            <mesh>
              <scale>1 1 1</scale>
              <uri>/home/ur/Desktop/test/UR_Robot_Disassembly/rokae/src/gazebo_link_attacher_ws/src/endeffector/meshes/camera_Link.STL</uri>
            </mesh>
          </geometry>
          <material>
            <script>
              <uri>__default__</uri>
              <name>__default__</name>
            </script>
          </material>
        </visual>
        <velocity_decay/>
        <self_collide>1</self_collide>
        <gravity>1</gravity>
        <velocity_decay/>
        <sensor name='camera' type='depth'>
          <always_on>1</always_on>
          <update_rate>20</update_rate>
          <camera name='__default__'>
            <horizontal_fov>1.0472</horizontal_fov>
            <image>
              <format>R8G8B8</format>
              <width>640</width>
              <height>480</height>
            </image>
            <clip>
              <near>0.05</near>
              <far>8</far>
            </clip>
          </camera>
          <plugin name='kinect_camera_controller' filename='libgazebo_ros_openni_kinect.so'>
            <cameraName>camera</cameraName>
            <alwaysOn>1</alwaysOn>
            <updateRate>10</updateRate>
            <imageTopicName>rgb/image_raw</imageTopicName>
            <depthImageTopicName>depth/image_raw</depthImageTopicName>
            <pointCloudTopicName>depth/points</pointCloudTopicName>
            <cameraInfoTopicName>rgb/camera_info</cameraInfoTopicName>
            <depthImageCameraInfoTopicName>depth/camera_info</depthImageCameraInfoTopicName>
            <frameName>camera_Link</frameName>
            <baseline>0.1</baseline>
            <distortion_k1>0.0</distortion_k1>
            <distortion_k2>0.0</distortion_k2>
            <distortion_k3>0.0</distortion_k3>
            <distortion_t1>0.0</distortion_t1>
            <distortion_t2>0.0</distortion_t2>
            <pointCloudCutoff>0.4</pointCloudCutoff>
            <robotNamespace>/</robotNamespace>
          </plugin>
          <pose frame=''>-0.18055 0.000297 0.073047 0.000188 -0.10472 -3.14159</pose>
        </sensor>
        <enable_wind>0</enable_wind>
        <kinematic>0</kinematic>
      </link>
      <joint name='wrist_3_joint' type='revolute'>
        <child>wrist_3_link</child>
        <parent>wrist_2_link</parent>
        <axis>
          <xyz>-0 1 -0</xyz>
          <limit>
            <lower>-6.28319</lower>
            <upper>6.28319</upper>
            <effort>56</effort>
            <velocity>3.14159</velocity>
          </limit>
          <dynamics>
            <damping>0</damping>
            <friction>0</friction>
            <spring_reference>0</spring_reference>
            <spring_stiffness>0</spring_stiffness>
          </dynamics>
          <use_parent_model_frame>1</use_parent_model_frame>
        </axis>
      </joint>
      <static>0</static>
      <plugin name='ros_control' filename='libgazebo_ros_control.so'>
        <robotNamespace>/</robotNamespace>
      </plugin>
      <pose frame=''>0 0 0.3 0 -0 0</pose>
    </model>
    <model name='M10_sleeve'>
      <link name='M10_sleeve_base_link'>
        <pose frame=''>0 0 0 0 -0 0</pose>
        <inertial>
          <pose frame=''>-0.000367 0 -0 0 -0 0</pose>
          <mass>0.010807</mass>
          <inertia>
            <ixx>9.0447e-07</ixx>
            <ixy>-5.476e-21</ixy>
            <ixz>9.2286e-20</ixz>
            <iyy>3.7372e-06</iyy>
            <iyz>2.1176e-22</iyz>
            <izz>3.7372e-06</izz>
          </inertia>
        </inertial>
        <collision name='M10_sleeve_base_link_collision'>
          <pose frame=''>0 0 0 0 -0 0</pose>
          <geometry>
            <mesh>
              <scale>1 1 1</scale>
              <uri>/home/ur/Desktop/test/UR_Robot_Disassembly/rokae/src/gazebo_link_attacher_ws/src/M10_sleeve/meshes/M10_sleeve_base_link.STL</uri>
            </mesh>
          </geometry>
          <max_contacts>10</max_contacts>
          <surface>
            <contact>
              <ode/>
            </contact>
            <bounce/>
            <friction>
              <torsional>
                <ode/>
              </torsional>
              <ode/>
            </friction>
          </surface>
        </collision>
        <visual name='M10_sleeve_base_link_visual'>
          <pose frame=''>0 0 0 0 -0 0</pose>
          <geometry>
            <mesh>
              <scale>1 1 1</scale>
              <uri>/home/ur/Desktop/test/UR_Robot_Disassembly/rokae/src/gazebo_link_attacher_ws/src/M10_sleeve/meshes/M10_sleeve_base_link.STL</uri>
            </mesh>
          </geometry>
        </visual>
        <self_collide>0</self_collide>
        <enable_wind>0</enable_wind>
        <kinematic>0</kinematic>
      </link>
      <pose frame=''>0 0 0 0 -0 0</pose>
    </model>
    <model name='M6_sleeve'>
      <link name='M6_sleeve_base_link'>
        <pose frame=''>0 0 0 0 -0 0</pose>
        <inertial>
          <pose frame=''>-0.00116 -0 0 0 -0 0</pose>
          <mass>0.010651</mass>
          <inertia>
            <ixx>8.1338e-07</ixx>
            <ixy>2.9592e-21</ixy>
            <ixz>-4.8249e-20</ixz>
            <iyy>3.3923e-06</iyy>
            <iyz>1.2184e-38</iyz>
            <izz>3.3923e-06</izz>
          </inertia>
        </inertial>
        <collision name='M6_sleeve_base_link_collision'>
          <pose frame=''>0 0 0 0 -0 0</pose>
          <geometry>
            <mesh>
              <scale>1 1 1</scale>
              <uri>/home/ur/Desktop/test/UR_Robot_Disassembly/rokae/src/gazebo_link_attacher_ws/src/M6_sleeve/meshes/M6_sleeve_base_link.STL</uri>
            </mesh>
          </geometry>
          <max_contacts>10</max_contacts>
          <surface>
            <contact>
              <ode/>
            </contact>
            <bounce/>
            <friction>
              <torsional>
                <ode/>
              </torsional>
              <ode/>
            </friction>
          </surface>
        </collision>
        <visual name='M6_sleeve_base_link_visual'>
          <pose frame=''>0 0 0 0 -0 0</pose>
          <geometry>
            <mesh>
              <scale>1 1 1</scale>
              <uri>/home/ur/Desktop/test/UR_Robot_Disassembly/rokae/src/gazebo_link_attacher_ws/src/M6_sleeve/meshes/M6_sleeve_base_link.STL</uri>
            </mesh>
          </geometry>
        </visual>
        <self_collide>0</self_collide>
        <enable_wind>0</enable_wind>
        <kinematic>0</kinematic>
      </link>
      <pose frame=''>0 0 0 0 -0 0</pose>
    </model>
    <model name='M8_sleeve'>
      <link name='M8_sleeve_base_link'>
        <pose frame=''>0 0 0 0 -0 0</pose>
        <inertial>
          <pose frame=''>-0.00074 0 -0 0 -0 0</pose>
          <mass>0.010747</mass>
          <inertia>
            <ixx>8.5579e-07</ixx>
            <ixy>-4.1281e-21</ixy>
            <ixz>6.8952e-20</ixz>
            <iyy>3.5699e-06</iyy>
            <iyz>0</iyz>
            <izz>3.5699e-06</izz>
          </inertia>
        </inertial>
        <collision name='M8_sleeve_base_link_collision'>
          <pose frame=''>0 0 0 0 -0 0</pose>
          <geometry>
            <mesh>
              <scale>1 1 1</scale>
              <uri>/home/ur/Desktop/test/UR_Robot_Disassembly/rokae/src/gazebo_link_attacher_ws/src/M8_sleeve/meshes/M8_sleeve_base_link.STL</uri>
            </mesh>
          </geometry>
          <max_contacts>10</max_contacts>
          <surface>
            <contact>
              <ode/>
            </contact>
            <bounce/>
            <friction>
              <torsional>
                <ode/>
              </torsional>
              <ode/>
            </friction>
          </surface>
        </collision>
        <visual name='M8_sleeve_base_link_visual'>
          <pose frame=''>0 0 0 0 -0 0</pose>
          <geometry>
            <mesh>
              <scale>1 1 1</scale>
              <uri>/home/ur/Desktop/test/UR_Robot_Disassembly/rokae/src/gazebo_link_attacher_ws/src/M8_sleeve/meshes/M8_sleeve_base_link.STL</uri>
            </mesh>
          </geometry>
        </visual>
        <self_collide>0</self_collide>
        <enable_wind>0</enable_wind>
        <kinematic>0</kinematic>
      </link>
      <pose frame=''>0 0 0 0 -0 0</pose>
    </model>
    <state world_name='default'>
      <sim_time>415 594000000</sim_time>
      <real_time>261 86169249</real_time>
      <wall_time>1652689507 601830736</wall_time>
      <iterations>18811</iterations>
      <model name='M10_sleeve'>
        <pose frame=''>0.485798 -2.3e-05 0.36093 0.038351 1.57057 -1.33579</pose>
        <scale>1 1 1</scale>
        <link name='M10_sleeve_base_link'>
          <pose frame=''>0.485798 -2.3e-05 0.36093 0.038351 1.57057 -1.33579</pose>
          <velocity>0.001901 -0.004459 -0.000941 0.100229 0.046905 -0.019218</velocity>
          <acceleration>0.57327 -1.49956 -0.284724 1.96209 0.402099 0.963854</acceleration>
          <wrench>0.006195 -0.016206 -0.003077 0 -0 0</wrench>
        </link>
      </model>
      <model name='M6_sleeve'>
        <pose frame=''>0.414303 8.3e-05 0.36091 -0.573319 1.57072 0.766721</pose>
        <scale>1 1 1</scale>
        <link name='M6_sleeve_base_link'>
          <pose frame=''>0.414303 8.3e-05 0.36091 -0.573319 1.57072 0.766721</pose>
          <velocity>0.003084 -0.001258 -0.000385 0.040364 0.074244 0.0797</velocity>
          <acceleration>-0.063662 0.015213 -9.72775 -2.73655 -1.04313 2.65193</acceleration>
          <wrench>-0.000678 0.000162 -0.10361 0 -0 0</wrench>
        </link>
      </model>
      <model name='M8_sleeve'>
        <pose frame=''>0.449909 -0.035713 0.360923 -0.545655 1.57047 1.2398</pose>
        <scale>1 1 1</scale>
        <link name='M8_sleeve_base_link'>
          <pose frame=''>0.449909 -0.035713 0.360923 -0.545655 1.57047 1.2398</pose>
          <velocity>-0.000217 0.00117 0.009567 -0.025903 -0.002157 0.016164</velocity>
          <acceleration>1.08648 4.14309 18.77 2.82578 -0.702401 -0.070024</acceleration>
          <wrench>0.011676 0.044526 0.201721 0 -0 0</wrench>
        </link>
      </model>
      <model name='ground_plane'>
        <pose frame=''>0 0 0 0 -0 0</pose>
        <scale>1 1 1</scale>
        <link name='link'>
          <pose frame=''>0 0 0 0 -0 0</pose>
          <velocity>0 0 0 0 -0 0</velocity>
          <acceleration>0 0 0 0 -0 0</acceleration>
          <wrench>0 0 0 0 -0 0</wrench>
        </link>
      </model>
      <model name='robot'>
        <pose frame=''>-0 0 0.3 -0 -0 -0</pose>
        <scale>1 1 1</scale>
        <link name='base_link'>
          <pose frame=''>-0 0 0.3 -0 -0 -0</pose>
          <velocity>0 -0 -0 0 -0 0</velocity>
          <acceleration>0 0 -0 -0 3e-06 1e-06</acceleration>
          <wrench>0.000227 0.000112 -2.9e-05 0 -0 0</wrench>
        </link>
        <link name='forearm_link'>
          <pose frame=''>-0.219822 -0.091054 1.04531 -1.57082 -0.10585 -2.74894</pose>
          <velocity>-0.000147 -0.00027 -9.2e-05 0.000138 -0.000132 0.000823</velocity>
          <acceleration>-0.018118 -0.005523 0.000975 -0.16061 -0.110183 0.029767</acceleration>
          <wrench>-0.070115 -0.021372 0.003775 0 -0 0</wrench>
        </link>
        <link name='shoulder_link'>
          <pose frame=''>0 -0 0.4807 2.3e-05 1.2e-05 0.392665</pose>
          <velocity>1e-06 -1e-06 -2e-06 0.000149 0.00016 0.000869</velocity>
          <acceleration>-0.000306 0.00024 0.00042 -0.033566 -0.057652 -0.005437</acceleration>
          <wrench>-0.00238 0.001865 0.003271 0 -0 0</wrench>
        </link>
        <link name='upper_arm_link'>
          <pose frame=''>1e-06 -0 0.480699 1.57085 1.17197 0.392706</pose>
          <velocity>2e-06 1e-06 1e-06 0.000166 -0.000381 0.000803</velocity>
          <acceleration>-0.008362 -0.00351 -0.003736 -0.075117 -0.067571 0.210774</acceleration>
          <wrench>-0.108119 -0.045387 -0.048311 0 -0 0</wrench>
        </link>
        <link name='wrist_1_link'>
          <pose frame=''>0.371912 -0.034474 0.984923 -1.57267 -1.55865 -2.74706</pose>
          <velocity>-0.000185 0.000227 1.2e-05 -0.000841 0.002052 0.000828</velocity>
          <acceleration>-0.016984 -0.002757 0.010199 0.00494 -0.036471 0.011176</acceleration>
          <wrench>-0.033288 -0.005405 0.01999 0 -0 0</wrench>
        </link>
        <link name='wrist_2_link'>
          <pose frame=''>0.482633 0.011383 0.98638 -1.55864 -0.024575 -1.17844</pose>
          <velocity>-0.000221 0.000321 -0.000237 -0.000607 0.002045 0.000836</velocity>
          <acceleration>-0.01727 -0.001874 0.010824 -0.0029 -0.015737 0.009841</acceleration>
          <wrench>-0.03385 -0.003672 0.021215 0 -0 0</wrench>
        </link>
        <link name='wrist_3_link'>
          <pose frame=''>0.485036 0.009278 0.869874 -3.12112 -0.018238 -1.56227</pose>
          <velocity>-0.000453 0.000251 -0.000239 -0.000619 0.002007 0.000821</velocity>
          <acceleration>-0.015919 -0.001974 0.010303 -0.000782 -0.011368 0.007683</acceleration>
          <wrench>-0.01549 -0.001921 0.010026 0 -0 0</wrench>
        </link>
      </model>
      <light name='sun'>
        <pose frame=''>0 0 10 0 -0 0</pose>
      </light>
    </state>
    <gui fullscreen='0'>
      <camera name='user_camera'>
        <pose frame=''>0.213843 -2.99074 0.786412 0 0.107643 1.24421</pose>
        <view_controller>orbit</view_controller>
        <projection_type>perspective</projection_type>
      </camera>
    </gui>
  </world>
</sdf>
