<?xml version="1.0" encoding="utf-8"?>
<!-- This URDF was automatically created by SolidWorks to URDF Exporter! Originally created by Stephen Brawner (brawner@gmail.com) 
     Commit Version: 1.5.1-0-g916b5db  Build Version: 1.5.7152.31018
     For more information, please see http://wiki.ros.org/sw_urdf_exporter -->
<robot  name="battery_pack">
  <link    name="battery_pack_link">
    <inertial>
      <origin        xyz="-0.69497 0.40355 -0.0048576"        rpy="0 0 0" />
      <mass        value="38.849" />
      <inertia        ixx="2.6252"        ixy="3.5672E-05"        ixz="-0.0040349"        iyy="6.7216"        iyz="-8.9999E-08"        izz="9.3409" />
    </inertial>
    <visual>
      <geometry>
        <mesh          filename="package://rokae_desk/meshes/battery_pack_link.stl" />
      </geometry>
      <origin        xyz="0 0 0"        rpy="0 0 0" />
      <material        name="">
        <color          rgba="0.79216 0.81961 0.93333 1" />
      </material>
    </visual>
    <collision>
      <origin        xyz="0 0 0"        rpy="0 0 0" />
      <geometry>
        <mesh
          filename="package://rokae_desk/meshes/battery_pack_link.stl" />
      </geometry>
    </collision>
  </link>

  <gazebo reference="battery_pack_link">
    <material>Gazebo/Orange</material>
  </gazebo>
  
  <link    name="luoshuan_Link">
    <inertial>
      <origin        xyz="-0.00727552152690839 0.047544175233636 0.015600434877913"
        rpy="0 0 0" />
      <mass        value="0.00893667958625815" />
      <inertia
        ixx="1.00378421041833E-07"
        ixy="-1.34648613478747E-13"
        ixz="7.18049496220953E-14"
        iyy="5.56080118731556E-07"
        iyz="5.3175741569067E-14"
        izz="5.5607994905101E-07" />
    </inertial>
    <visual>
      <origin        xyz="0 0 0"        rpy="0 0 0" />
      <geometry>
        <mesh          filename="package://rokae_desk/meshes/luoshuan_Link.stl" />
      </geometry>
      <material        name="">
        <color          rgba="0.776470588235294 0.756862745098039 0.737254901960784 1" />
      </material>
    </visual>
    <collision>
      <origin        xyz="0 0 0"        rpy="0 0 0" />
      <geometry>
        <mesh          filename="package://rokae_desk/meshes/luoshuan_Link.stl" />
      </geometry>
    </collision>
  </link>

  <joint    name="luoshuan"    type="continuous">
    <origin      xyz="0.016544 -0.0094533 0"      rpy="1.8719 1.5708 0" />
    <parent      link="battery_pack_link" />
    <child      link="luoshuan_Link" />
    <axis      xyz="1 0 0" />
    <limit      lower="0"      upper="0"      effort="0"      velocity="0" />
  </joint>

  <link    name="luomu_Link">
  
    <inertial>
      <origin        xyz="0.0499993014489127 -0.00197272491730389 -0.00260060062372346"   rpy="0 0 0" />
      <mass        value="0.00265736664598247" />
      <inertia
        ixx="2.79753335550581E-08"
        ixy="5.00698636970922E-14"
        ixz="1.69540696961174E-14"
        iyy="2.79767293623279E-08"
        iyz="-6.75598040574546E-14"
        izz="4.4615609147972E-08" />
    </inertial>

    <visual>
      <origin        xyz="0 0 0"        rpy="0 0 0" />
      <geometry>
        <mesh          filename="package://rokae_desk/meshes/luomu_Link.stl" />
      </geometry>
      <material        name="">
        <color          rgba="0.776470588235294 0.756862745098039 0.737254901960784 1" />
      </material>
    </visual>

    <collision>
      <origin   xyz="0 0 0"   rpy="0 0 0" />
      <geometry>
        <mesh          filename="package://rokae_desk/meshes/luomu_Link.stl" />
      </geometry>
    </collision>
  </link>

  <joint    name="luomu"    type="fixed">
    <origin      xyz="0.016544 -0.0094533 0"      rpy="0 0 -0.57871" />
    <parent      link="battery_pack_link" />
    <child      link="luomu_Link" />
    <axis      xyz="0 0 0" />
  </joint>

</robot>