<robot name="rokae" xmlns:xacro="http://www.ros.org/wiki/xacro">

  <!-- Constants for robot dimensions -->
 
  <!-- Import all Gazebo-customization elements, including Gazebo colors -->
  <!-- Import Rviz colors -->
  <xacro:include filename="$(find rokae_desk)/urdf/materials.xacro" />
  <xacro:property name="nameofManipulator" value = "rokae"/>

  <!-- Used for fixing robot to Gazebo 'base_link' -->
  <!-- <link name="world"/>
    <joint name="fixed" type="fixed">
    <parent link="world"/>
    <child link="${nameofManipulator}_base"/>
  </joint>
  
  -->



<!--base-->
  <link name="${nameofManipulator}_base">
    <visual>
      <geometry>
        <mesh filename="package://${nameofManipulator}_desk/meshes/visual/${nameofManipulator}_base.stl" scale="0.001 0.001 0.001"/>
      </geometry>
       <origin rpy="0 0 0" xyz="0.0 0.0 0.0"/>
       <material name="white"/>
    </visual>
    <inertial>
      
  <mass value="5.48267"/>
  <inertia ixx="0.056" ixy="0" ixz="0" iyy="0.066" iyz="0" izz="0.035"/>
  <origin rpy="0 0 0" xyz="-0.0183 0 0.067"/> 
    </inertial>
    <collision>
      <geometry>
        <mesh filename="package://${nameofManipulator}_desk/meshes/collision/${nameofManipulator}_base.stl" scale="0.001 0.001 0.001"/>
      </geometry>
      <origin rpy="0 0 0" xyz="0.0 0.0 0.0"/>
    </collision>
  </link>
  
  <joint name="xmate_joint_1" type="revolute">
    <parent link="${nameofManipulator}_base"/>
    <child link="${nameofManipulator}_link1"/>
 <limit effort="300" lower="-3.0527" upper="3.0527" velocity="10"/>
    <axis xyz="0 0 1"/>
    <origin rpy="0 0 0" xyz="0 0 0"/>
 </joint>
 
<transmission name="tran1">
    <type>transmission_interface/SimpleTransmission</type>
    <joint name="xmate_joint_1">
<hardwareInterface>hardware_interface/PositionJointInterface</hardwareInterface>
    </joint>
    <actuator name="motor1">
<hardwareInterface>hardware_interface/PositionJointInterface</hardwareInterface>
      <mechanicalReduction>1</mechanicalReduction>
    </actuator>
  </transmission>
  
  <gazebo reference="${nameofManipulator}_base">
     <material>Gazebo/GreyTransparent</material>
  </gazebo>
  
  
<!--link 1-->  
  <link name="${nameofManipulator}_link1">
    <visual>
      <geometry>
        <mesh filename="package://${nameofManipulator}_desk/meshes/visual/${nameofManipulator}_link1.stl" scale="0.001 0.001 0.001"/>
      </geometry>
      <origin rpy="0 0 0" xyz="0 0 0"/>
      <material name="white"/>
    </visual>
    
    <inertial>      
     <mass value="5.96204"/>
     <inertia ixx="0.051" ixy="0" ixz="0" iyy="0.049" iyz="-0.007" izz="7.176"/>
     <origin rpy="0 0 0" xyz="0 -0.017 0.320"/>

     </inertial>
    
    
    <collision>
      <geometry>
        <mesh filename="package://${nameofManipulator}_desk/meshes/collision/${nameofManipulator}_link1.stl" scale="0.001 0.001 0.001"/>
      </geometry>
       <origin rpy="0 0 0" xyz="0 0 0"/>
    </collision>
  </link>
  
  <joint name="xmate_joint_2" type="revolute">
    <parent link="${nameofManipulator}_link1"/>
    <child link="${nameofManipulator}_link2"/>
  <limit effort="300" lower="-2.0933" upper="2.0933" velocity="10"/>
    <axis xyz="0 1 0"/>
	<origin rpy="0 0 0" xyz="0 0 0.404"/>
    </joint>
  
   <transmission name="tran2">
     <type>transmission_interface/SimpleTransmission</type>
    <joint name="xmate_joint_2">
<hardwareInterface>hardware_interface/PositionJointInterface</hardwareInterface>
    </joint>
    <actuator name="motor2">
<hardwareInterface>hardware_interface/PositionJointInterface</hardwareInterface>
      <mechanicalReduction>1</mechanicalReduction>
    </actuator>
  </transmission>
  
  <gazebo reference="${nameofManipulator}_link1">
     <material>Gazebo/GreyTransparent</material>
  </gazebo>



<!--link 2-->  
  <link name="${nameofManipulator}_link2">
    <visual>
      <geometry>
        <mesh filename="package://${nameofManipulator}_desk/meshes/visual/${nameofManipulator}_link2.stl" scale="0.001 0.001 0.001"/>
      </geometry>
     <origin rpy="0 0 0" xyz="0 0 0.0"/>
     <material name="white"/>
    </visual>
    
    
    <inertial>
    <mass value="5.40302"/>
    <inertia ixx="0.070" ixy="0" ixz="0" iyy="7.230" iyz="-0.014" izz="0.011"/>
    <origin rpy="0 0 0" xyz="0 0.032 0.093"/>
    </inertial>
    
    <collision>
      <geometry>
        <mesh filename="package://${nameofManipulator}_desk/meshes/collision/${nameofManipulator}_link2.stl" scale="0.001 0.001 0.001"/>
      </geometry>
      <origin rpy="0 0 0" xyz="0 0 0.0"/>
    </collision>
  </link>
 
   
  <joint name="xmate_joint_3" type="revolute">
    <parent link="${nameofManipulator}_link2"/>
    <child link="${nameofManipulator}_link3"/>
  <limit effort="300" lower="-3.0527" upper="3.0527" velocity="10"/>
    <axis xyz="0 0 1"/>
    <origin rpy="0 0 0" xyz="0 0 0.23743878"/>
  </joint>
  
  
   <transmission name="tran3">
    <type>transmission_interface/SimpleTransmission</type>
    <joint name="xmate_joint_3">
<hardwareInterface>hardware_interface/PositionJointInterface</hardwareInterface>
    </joint>
    <actuator name="motor3">
<hardwareInterface>hardware_interface/PositionJointInterface</hardwareInterface>
      <mechanicalReduction>1</mechanicalReduction>
    </actuator>
  </transmission>

  <gazebo reference="${nameofManipulator}_link2">
     <material>Gazebo/GreyTransparent</material>
  </gazebo>


<!--${nameofManipulator}_link 3--> 
  <link name="${nameofManipulator}_link3">
    <visual>
      <geometry>
        <mesh filename="package://${nameofManipulator}_desk/meshes/visual/${nameofManipulator}_link3.stl" scale="0.001 0.001 0.001"/>
      </geometry>
	<origin rpy="0 0 0" xyz="0 0 0.15549959"/>
      <material name="white"/>
    </visual>

    <inertial>    
    <mass value="3.95735"/>
    <inertia ixx="0.022" ixy="0" ixz="0" iyy="0.021" iyz="-0.002" izz="1.12"/>
    <origin rpy="0 0 0" xyz="0 -0.013 -0.067"/>

    </inertial>
    
    <collision>
      <geometry>
        <mesh filename="package://${nameofManipulator}_desk/meshes/collision/${nameofManipulator}_link3.stl" scale="0.001 0.001 0.001"/>
      </geometry>
         <origin rpy="0 0 0" xyz="0 0 0.15549959"/>
      </collision>
  </link>
 
  <joint name="xmate_joint_4" type="revolute">
    <parent link="${nameofManipulator}_link3"/>
    <child link="${nameofManipulator}_link4"/>
   <limit effort="300" lower="-2.0933" upper="2.0933" velocity="10"/>
<!--     lower="-2.79" upper="2.79" -->
    <axis xyz="0 1 0"/>
<!--     <origin rpy="0 0 0" xyz="0.585 0.0 0.035"/> -->
    <origin rpy="0 0 0" xyz="0 0 0.15549959"/>
  </joint>
  
  <transmission name="tran4">
    <type>transmission_interface/SimpleTransmission</type>
    <joint name="xmate_joint_4">
<hardwareInterface>hardware_interface/PositionJointInterface</hardwareInterface>
    </joint>
    <actuator name="motor4">
<hardwareInterface>hardware_interface/PositionJointInterface</hardwareInterface>
      <mechanicalReduction>1</mechanicalReduction>
    </actuator>
  </transmission>

  <gazebo reference="${nameofManipulator}_link3">
     <material>Gazebo/GreyTransparent</material>
  </gazebo>

<!--link 4--> 
  <link name="${nameofManipulator}_link4">
    <visual>
      <geometry>
        <mesh filename="package://${nameofManipulator}_desk/meshes/visual/${nameofManipulator}_link4.stl" scale=".001 0.001 0.001"/>
      </geometry>
	<origin rpy="0 0 0" xyz="0.0 0.0 0.0"/>
      <material name="white"/>
    </visual>
    <inertial>    
    <mass value="2.91217"/>
    <inertia ixx="0.024" ixy="0" ixz="0" iyy="1.138" iyz="-0.004" izz="0.005"/>
    <origin rpy="0 0 0" xyz="0 0.026 0.068"/>

    </inertial>
    <collision>
      <geometry>
        <mesh filename="package://${nameofManipulator}_desk/meshes/collision/${nameofManipulator}_link4.stl" scale="0.001 0.001 0.001"/>
      </geometry>
	<origin rpy="0 0 0" xyz="0.0 0.0 0.0"/>
    </collision>
  </link>
  
  
  <joint name="xmate_joint_5" type="revolute">
    <parent link="${nameofManipulator}_link4"/>
    <child link="${nameofManipulator}_link5"/>
  <limit effort="300" lower="-3.0527" upper="3.0527" velocity="10"/>
    <axis xyz="0 0 1"/>
   <origin rpy="0 0 0" xyz="0 0 0.22044633"/>
  </joint>
  
  
  <transmission name="tran5">
    <type>transmission_interface/SimpleTransmission</type>
    <joint name="xmate_joint_5">
<hardwareInterface>hardware_interface/PositionJointInterface</hardwareInterface>
    </joint>
    <actuator name="motor5">
<hardwareInterface>hardware_interface/PositionJointInterface</hardwareInterface>
      <mechanicalReduction>1</mechanicalReduction>
    </actuator>
  </transmission>

  <gazebo reference="${nameofManipulator}_link4">
     <material>Gazebo/GreyTransparent</material>
  </gazebo>




<!--link 5--> 
  <link name="${nameofManipulator}_link5">
    <visual>
      <geometry>
        <mesh filename="package://${nameofManipulator}_desk/meshes/visual/${nameofManipulator}_link5.stl" scale="0.001 0.001 0.001"/>
      </geometry>
       <origin rpy="0 0 0" xyz="0 0 0.14512568"/>
      <material name="white"/>
      </visual>

    <inertial>

    <mass value="2.47056"/>
    <inertia ixx="0.019" ixy="0" ixz="0" iyy="0.018" iyz="-0.002" izz="0.339"/>
    <origin rpy="0 0 0" xyz="0 -0.014 -0.079"/>

    </inertial>
    
    <collision>
      <geometry>
        <mesh filename="package://${nameofManipulator}_desk/meshes/collision/${nameofManipulator}_link5.stl" scale="0.001 0.001 0.001"/>
      </geometry>
       <origin rpy="0 0 0" xyz="0 0 0.14512568"/>
    </collision>
  </link>
  
  <joint name="xmate_joint_6" type="revolute">
    <parent link="${nameofManipulator}_link5"/>
    <child link="${nameofManipulator}_link6"/>
   <limit effort="300" lower="-2.0933" upper="2.0933" velocity="10"/>
    <axis xyz="0 1 0"/>
    <origin rpy="0.0 0.0 0" xyz="0 0 0.14512568" />
  </joint>
  
  
  <transmission name="tran6">
    <type>transmission_interface/SimpleTransmission</type>
    <joint name="xmate_joint_6">
<hardwareInterface>hardware_interface/PositionJointInterface</hardwareInterface>
    </joint>
    <actuator name="motor6">
<hardwareInterface>hardware_interface/PositionJointInterface</hardwareInterface>
      <mechanicalReduction>1</mechanicalReduction>
    </actuator>
  </transmission>

  <gazebo reference="${nameofManipulator}_link5">
     <material>Gazebo/GreyTransparent</material>
  </gazebo>



<!--link 6--> 
  <link name="${nameofManipulator}_link6">
    <visual>
      <geometry>
        <mesh filename="package://${nameofManipulator}_desk/meshes/visual/${nameofManipulator}_link6.stl" scale="0.001 0.001 0.001"/>
      </geometry>
	<origin rpy="0 0 0" xyz="0.0 0.0 0.0"/>
      <material name="white"/>
    </visual>
    
    <inertial>
      <mass value="2.16053"/>
    <inertia ixx="0.016" ixy="0" ixz="0" iyy="0.351" iyz="-0.003" izz="0.003"/>
      <origin rpy="0 0 0" xyz="0 0.020 0.085"/>
    </inertial>
    
    <collision>
      <geometry>
        <mesh filename="package://${nameofManipulator}_desk/meshes/collision/${nameofManipulator}_link6.stl" scale="0.001 0.001 0.001"/>
      </geometry>
	<origin rpy="0 0 0" xyz="0.0 0.0 0.0"/>
    </collision>
  </link>

  <joint name="xmate_joint_7" type="revolute">
    <parent link="${nameofManipulator}_link6"/>
    <child link="${nameofManipulator}_link7"/>
   <limit effort="300" lower="-6.283" upper="6.283" velocity="10"/>
    <axis xyz="0 0 1"/>
    <origin rpy="0.0 0.0 0.0" xyz="0 0 0.25090877" />
  </joint>
  
  
  <transmission name="tran7">
    <type>transmission_interface/SimpleTransmission</type>
    <joint name="xmate_joint_7">
<hardwareInterface>hardware_interface/PositionJointInterface</hardwareInterface>
    </joint>
    <actuator name="motor7">
<hardwareInterface>hardware_interface/PositionJointInterface</hardwareInterface>
      <mechanicalReduction>1</mechanicalReduction>
    </actuator>
  </transmission>

  <gazebo reference="${nameofManipulator}_link6">
     <material>Gazebo/GreyTransparent</material>
  </gazebo>



<!--link 7--> 
  <link name="${nameofManipulator}_link7">
    <visual>
      <geometry>
        <mesh filename="package://${nameofManipulator}_desk/meshes/visual/${nameofManipulator}_link7.stl" scale="0.001 0.001 0.001"/>
      </geometry>
	    <origin rpy="0 0 0" xyz="0 0 0"/>
      <material name="white"/>
    </visual>
    
    <inertial>
      <mass value="1.26834"/>
      <inertia ixx="0.002" ixy="-0.000000" ixz="-0.000000" iyy="0.001" iyz="-0.000000" izz="0.337"/>
      <origin rpy="0 0 0" xyz="0 0.012 -0.052"/>
    </inertial>
    
    <collision>
      <geometry>
        <mesh filename="package://${nameofManipulator}_desk/meshes/collision/${nameofManipulator}_link7.stl" scale="0.001 0.001 0.001"/>
      </geometry>
	    <origin rpy="0 0 0" xyz="0 0 0"/>
    </collision>
  </link>
  

<!-- 

    <joint name="xmate_joint_8" type="revolute">
    <parent link="${nameofManipulator}_link7"/>
    <child link="taotong_link8"/>
      <limit effort="300" lower="-6.283" upper="6.283" velocity="10"/>
    <axis xyz="0 0 1"/>
    <origin rpy="0.0 0.0 0.0" xyz="0 0 0.25090877" />
    </joint>
   -->
  
  <!-- <transmission name="tran8">
    <type>transmission_interface/SimpleTransmission</type>
    <joint name="xmate_joint_8">
<hardwareInterface>hardware_interface/PositionJointInterface</hardwareInterface>
    </joint>
    <actuator name="motor8">
<hardwareInterface>hardware_interface/PositionJointInterface</hardwareInterface>
      <mechanicalReduction>1</mechanicalReduction>
    </actuator>
  </transmission> -->
  

  <gazebo reference="${nameofManipulator}_link7">
     <material>Gazebo/GreyTransparent</material>
  </gazebo>






<!-- ros_control plugin -->
<gazebo>
  <plugin name="gazebo_ros_control" filename="libgazebo_ros_control.so">
    <robotNamespace>/rokae</robotNamespace>
    <robotSimType>gazebo_ros_control/DefaultRobotHWSim</robotSimType>
    <legacyModeNS>true</legacyModeNS>
  </plugin>
</gazebo>


</robot>
