<?xml version="1.0" encoding="utf-8"?>
<!-- This URDF was automatically created by SolidWorks to URDF Exporter! Originally created by Stephen Brawner (brawner@gmail.com) 
     Commit Version: 1.6.0-4-g7f85cfe  Build Version: 1.6.7995.38578
     For more information, please see http://wiki.ros.org/sw_urdf_exporter -->
<robot
  name="endeffector">
  <link
    name="end_effector_base_Link">
    <inertial>
      <origin
        xyz="0.059705 0.10557 0.16503"
        rpy="0 0 0" />
      <mass
        value="0.65151" />
      <inertia
        ixx="0.00070551"
        ixy="-1.1407E-06"
        ixz="-1.59E-05"
        iyy="0.0016582"
        iyz="5.8675E-06"
        izz="0.0011997" />
    </inertial>
    <visual>
      <origin
        xyz="0 0 0"
        rpy="0 0 0" />
      <geometry>
        <mesh
          filename="package://endeffector/meshes/end_effector_base_Link.STL" />
      </geometry>
      <material
        name="">
        <color
          rgba="0.79216 0.81961 0.93333 1" />
      </material>
    </visual>
    <collision>
      <origin
        xyz="0 0 0"
        rpy="0 0 0" />
      <geometry>
        <mesh
          filename="package://endeffector/meshes/end_effector_base_Link.STL" />
      </geometry>
    </collision>
  </link>
  <link
    name="camera_Link">
    <inertial>
      <origin
        xyz="4.6756E-05 -0.00051236 0.012832"
        rpy="0 0 0" />
      <mass
        value="0.071592" />
      <inertia
        ixx="1.9381E-05"
        ixy="-4.8E-08"
        ixz="4.5478E-09"
        iyy="2.0232E-05"
        iyz="-5.0299E-10"
        izz="3.1685E-05" />
    </inertial>
    <visual>
      <origin
        xyz="0 0 0"
        rpy="0 0 0" />
      <geometry>
        <mesh
          filename="package://endeffector/meshes/camera_Link.STL" />
      </geometry>
      <material
        name="">
        <color
          rgba="0.79216 0.81961 0.93333 1" />
      </material>
    </visual>
    <collision>
      <origin
        xyz="0 0 0"
        rpy="0 0 0" />
      <geometry>
        <mesh
          filename="package://endeffector/meshes/camera_Link.STL" />
      </geometry>
    </collision>
  </link>
  <joint
    name="camera_Joint"
    type="fixed">
    <origin
      xyz="0.23581 -0.13981 0.10673"
      rpy="-1.4894 1.569 -0.0064713" />
    <parent
      link="end_effector_base_Link" />
    <child
      link="camera_Link" />
    <axis
      xyz="0 0 0" />
  </joint>
  <link
    name="rotate_Link">
    <inertial>
      <origin
        xyz="-3.0605E-11 -4.037E-12 0.11365"
        rpy="0 0 0" />
      <mass
        value="0.047987" />
      <inertia
        ixx="0.00022999"
        ixy="-4.2745E-16"
        ixz="1.5549E-14"
        iyy="0.00022999"
        iyz="-1.7124E-13"
        izz="1.8252E-06" />
    </inertial>
    <visual>
      <origin
        xyz="0 0 0"
        rpy="0 0 0" />
      <geometry>
        <mesh
          filename="package://endeffector/meshes/rotate_Link.STL" />
      </geometry>
      <material
        name="">
        <color
          rgba="1 1 1 1" />
      </material>
    </visual>
    <collision>
      <origin
        xyz="0 0 0"
        rpy="0 0 0" />
      <geometry>
        <mesh
          filename="package://endeffector/meshes/rotate_Link.STL" />
      </geometry>
    </collision>
  </link>
  <joint
    name="rotate_Joint"
    type="continuous">
    <origin
      xyz="0.071989 -0.30978 0.10306"
      rpy="-1.5877 0.0017984 -3.1247" />
    <parent
      link="end_effector_base_Link" />
    <child
      link="rotate_Link" />
    <axis
      xyz="0 0 0" />
  </joint>
</robot>