<sdf version='1.6'>
  <world name='default'>
    <light name='sun' type='directional'>
      <cast_shadows>1</cast_shadows>
      <pose frame=''>0 0 10 0 -0 0</pose>
      <diffuse>0.8 0.8 0.8 1</diffuse>
      <specular>0.2 0.2 0.2 1</specular>
      <attenuation>
        <range>1000</range>
        <constant>0.9</constant>
        <linear>0.01</linear>
        <quadratic>0.001</quadratic>
      </attenuation>
      <direction>-0.5 0.1 -0.9</direction>
    </light>
    <model name='ground_plane'>
      <static>1</static>
      <link name='link'>
        <collision name='collision'>
          <geometry>
            <plane>
              <normal>0 0 1</normal>
              <size>100 100</size>
            </plane>
          </geometry>
          <surface>
            <contact>
              <collide_bitmask>65535</collide_bitmask>
              <ode/>
            </contact>
            <friction>
              <ode>
                <mu>100</mu>
                <mu2>50</mu2>
              </ode>
              <torsional>
                <ode/>
              </torsional>
            </friction>
            <bounce/>
          </surface>
          <max_contacts>10</max_contacts>
        </collision>
        <visual name='visual'>
          <cast_shadows>0</cast_shadows>
          <geometry>
            <plane>
              <normal>0 0 1</normal>
              <size>100 100</size>
            </plane>
          </geometry>
          <material>
            <script>
              <uri>file://media/materials/scripts/gazebo.material</uri>
              <name>Gazebo/Grey</name>
            </script>
          </material>
        </visual>
        <self_collide>0</self_collide>
        <enable_wind>0</enable_wind>
        <kinematic>0</kinematic>
      </link>
    </model>
    <gravity>0 0 -9.8</gravity>
    <magnetic_field>6e-06 2.3e-05 -4.2e-05</magnetic_field>
    <atmosphere type='adiabatic'/>
    <physics name='default_physics' default='0' type='ode'>
      <max_step_size>0.001</max_step_size>
      <real_time_factor>1</real_time_factor>
      <real_time_update_rate>1000</real_time_update_rate>
    </physics>
    <scene>
      <ambient>0.4 0.4 0.4 1</ambient>
      <background>0.7 0.7 0.7 1</background>
      <shadows>1</shadows>
    </scene>
    <audio>
      <device>default</device>
    </audio>
    <wind/>
    <spherical_coordinates>
      <surface_model>EARTH_WGS84</surface_model>
      <latitude_deg>0</latitude_deg>
      <longitude_deg>0</longitude_deg>
      <elevation>0</elevation>
      <heading_deg>0</heading_deg>
    </spherical_coordinates>
    <model name='battery_pack_description'>
      <link name='battery_pack_link'>
        <pose frame=''>0 0 0 0 -0 0</pose>
        <inertial>
          <pose frame=''>-0.007669 -0.003733 0.000318 0 -0 0</pose>
          <mass>0.0447654</mass>
          <inertia>
            <ixx>7.43409e-06</ixx>
            <ixy>-1.20089e-06</ixy>
            <ixz>2.46892e-07</ixz>
            <iyy>1.39433e-05</iyy>
            <iyz>-3.16493e-08</iyz>
            <izz>1.32873e-05</izz>
          </inertia>
        </inertial>
        <collision name='battery_pack_link_collision'>
          <pose frame=''>0 0 0 0 -0 0</pose>
          <geometry>
            <mesh>
              <scale>1 1 1</scale>
              <uri>/home/hp/Desktop/rokae0717/src/rokae_description/meshes/battery_pack_link.stl</uri>
            </mesh>
          </geometry>
          <surface>
            <contact>
              <ode/>
            </contact>
            <friction>
              <ode/>
              <torsional>
                <ode/>
              </torsional>
            </friction>
            <bounce/>
          </surface>
          <max_contacts>10</max_contacts>
        </collision>
        <collision name='battery_pack_link_fixed_joint_lump__luomu_Link_collision_1'>
          <pose frame=''>0.016544 -0.009453 0 0 0 -0.57871</pose>
          <geometry>
            <mesh>
              <scale>1 1 1</scale>
              <uri>/home/hp/Desktop/rokae0717/src/rokae_description/meshes/luomu_Link.stl</uri>
            </mesh>
          </geometry>
          <surface>
            <contact>
              <ode/>
            </contact>
            <friction>
              <ode/>
              <torsional>
                <ode/>
              </torsional>
            </friction>
            <bounce/>
          </surface>
          <max_contacts>10</max_contacts>
        </collision>
        <visual name='battery_pack_link_visual'>
          <pose frame=''>0 0 0 0 -0 0</pose>
          <geometry>
            <mesh>
              <scale>1 1 1</scale>
              <uri>/home/hp/Desktop/rokae0717/src/rokae_description/meshes/battery_pack_link.stl</uri>
            </mesh>
          </geometry>
          <material>
            <script>
              <name>Gazebo/Black</name>
              <uri>file://media/materials/scripts/gazebo.material</uri>
            </script>
          </material>
        </visual>
        <visual name='battery_pack_link_fixed_joint_lump__luomu_Link_visual_1'>
          <pose frame=''>0.016544 -0.009453 0 0 0 -0.57871</pose>
          <geometry>
            <mesh>
              <scale>1 1 1</scale>
              <uri>/home/hp/Desktop/rokae0717/src/rokae_description/meshes/luomu_Link.stl</uri>
            </mesh>
          </geometry>
          <material>
            <script>
              <name>Gazebo/Gray</name>
              <uri>file://media/materials/scripts/gazebo.material</uri>
            </script>
          </material>
        </visual>
        <velocity_decay/>
        <gravity>1</gravity>
        <velocity_decay/>
        <self_collide>0</self_collide>
        <enable_wind>0</enable_wind>
        <kinematic>0</kinematic>
      </link>
      <link name='luoshuan_Link'>
        <pose frame=''>0.016544 -0.009453 0 -1.26969 1.57079 3.14159</pose>
        <inertial>
          <pose frame=''>-0.007276 -0 0 0 -0 0</pose>
          <mass>0.00893668</mass>
          <inertia>
            <ixx>1.00378e-07</ixx>
            <ixy>-1.34649e-13</ixy>
            <ixz>7.18049e-14</ixz>
            <iyy>5.5608e-07</iyy>
            <iyz>5.31757e-14</iyz>
            <izz>5.5608e-07</izz>
          </inertia>
        </inertial>
        <collision name='luoshuan_Link_collision'>
          <pose frame=''>0 0 0 0 -0 0</pose>
          <geometry>
            <mesh>
              <scale>1 1 1</scale>
              <uri>/home/hp/Desktop/rokae0717/src/rokae_description/meshes/luoshuan_Link.stl</uri>
            </mesh>
          </geometry>
          <surface>
            <contact>
              <ode/>
            </contact>
            <friction>
              <ode/>
              <torsional>
                <ode/>
              </torsional>
            </friction>
            <bounce/>
          </surface>
          <max_contacts>10</max_contacts>
        </collision>
        <visual name='luoshuan_Link_visual'>
          <pose frame=''>0 0 0 0 -0 0</pose>
          <geometry>
            <mesh>
              <scale>1 1 1</scale>
              <uri>/home/hp/Desktop/rokae0717/src/rokae_description/meshes/luoshuan_Link.stl</uri>
            </mesh>
          </geometry>
          <material>
            <script>
              <name>Gazebo/Gray</name>
              <uri>file://media/materials/scripts/gazebo.material</uri>
            </script>
          </material>
        </visual>
        <gravity>1</gravity>
        <velocity_decay/>
        <self_collide>0</self_collide>
        <enable_wind>0</enable_wind>
        <kinematic>0</kinematic>
      </link>
      <joint name='luoshuan' type='revolute'>
        <child>luoshuan_Link</child>
        <parent>battery_pack_link</parent>
        <axis>
          <xyz>-4e-06 0 -1</xyz>
          <limit>
            <lower>0</lower>
            <upper>0</upper>
            <effort>0</effort>
            <velocity>0</velocity>
          </limit>
          <dynamics>
            <spring_reference>0</spring_reference>
            <spring_stiffness>0</spring_stiffness>
          </dynamics>
          <use_parent_model_frame>1</use_parent_model_frame>
        </axis>
      </joint>
      <pose frame=''>0 0 0 0 -0 0</pose>
    </model>
    <state world_name='default'>
      <sim_time>142 238000000</sim_time>
      <real_time>0 0</real_time>
      <wall_time>1626785837 808571592</wall_time>
      <iterations>0</iterations>
      <model name='battery_pack_description'>
        <pose frame=''>0.757028 -0.133095 0.866927 -5.7e-05 -3e-06 3.02176</pose>
        <scale>1 1 1</scale>
        <link name='battery_pack_link'>
          <pose frame=''>0.757028 -0.133095 0.866927 -5.7e-05 -3e-06 3.02176</pose>
          <velocity>0.000499 0.003578 0.005627 -0.182371 0.024227 -0.001494</velocity>
          <acceleration>0 0 0 -8.9e-05 -0.000488 0.003261</acceleration>
          <wrench>0 0 0 0 -0 0</wrench>
        </link>
        <link name='luoshuan_Link'>
          <pose frame=''>0.741732 -0.121732 0.866927 0.314825 1.57074 1.46468</pose>
          <velocity>0.000328 0.00216 0.006672 -0.184149 0.022805 -0.00488</velocity>
          <acceleration>0 0 0 -9.1e-05 -0.000736 0</acceleration>
          <wrench>0 0 0 0 -0 0</wrench>
        </link>
      </model>
      <model name='cafe_table'>
        <pose frame=''>0.701917 0.035179 0 0 -0 0</pose>
        <scale>1 1 1</scale>
        <link name='link'>
          <pose frame=''>0.701917 0.035179 0 0 -0 0</pose>
          <velocity>0 0 0 0 -0 0</velocity>
          <acceleration>0 0 0 0 -0 0</acceleration>
          <wrench>0 0 0 0 -0 0</wrench>
        </link>
      </model>
      <model name='ground_plane'>
        <pose frame=''>0 0 0 0 -0 0</pose>
        <scale>1 1 1</scale>
        <link name='link'>
          <pose frame=''>0 0 0 0 -0 0</pose>
          <velocity>0 0 0 0 -0 0</velocity>
          <acceleration>0 0 0 0 -0 0</acceleration>
          <wrench>0 0 0 0 -0 0</wrench>
        </link>
      </model>
      <model name='kinect'>
        <pose frame=''>0.535864 -0.337927 1.68453 0 1.49211 0</pose>
        <scale>1 1 1</scale>
        <link name='link'>
          <pose frame=''>0.535864 -0.337927 1.68453 0 1.49211 0</pose>
          <velocity>0 0 0 0 -0 0</velocity>
          <acceleration>0 0 0 0 -0 0</acceleration>
          <wrench>0 0 0 0 -0 0</wrench>
        </link>
      </model>
      <model name='rokae'>
        <pose frame=''>0 0 0 0 -0 0</pose>
        <scale>1 1 1</scale>
        <link name='rokae_base'>
          <pose frame=''>0 0 0 0 -0 0</pose>
          <velocity>0 0 0 0 -0 0</velocity>
          <acceleration>0 0 0 0 -0 0</acceleration>
          <wrench>0 0 0 0 -0 0</wrench>
        </link>
        <link name='rokae_link1'>
          <pose frame=''>0 0 0 0 -0 0</pose>
          <velocity>0 0 0 0 -0 0</velocity>
          <acceleration>0 0 0 0 -0 0</acceleration>
          <wrench>0 0 0 0 -0 0</wrench>
        </link>
        <link name='rokae_link2'>
          <pose frame=''>0 0 0.404 0 -0 0</pose>
          <velocity>0 0 0 0 -0 0</velocity>
          <acceleration>0 0 0 0 -0 0</acceleration>
          <wrench>0 0 0 0 -0 0</wrench>
        </link>
        <link name='rokae_link3'>
          <pose frame=''>0 0 0.641439 0 -0 0</pose>
          <velocity>0 0 0 0 -0 0</velocity>
          <acceleration>0 0 0 0 -0 0</acceleration>
          <wrench>0 0 0 0 -0 0</wrench>
        </link>
        <link name='rokae_link4'>
          <pose frame=''>0 0 0.796938 0 -0 0</pose>
          <velocity>0 0 0 0 -0 0</velocity>
          <acceleration>0 0 0 0 -0 0</acceleration>
          <wrench>0 0 0 0 -0 0</wrench>
        </link>
        <link name='rokae_link5'>
          <pose frame=''>0 0 1.01738 0 -0 0</pose>
          <velocity>0 0 0 0 -0 0</velocity>
          <acceleration>0 0 0 0 -0 0</acceleration>
          <wrench>0 0 0 0 -0 0</wrench>
        </link>
        <link name='rokae_link6'>
          <pose frame=''>0 0 1.16251 0 -0 0</pose>
          <velocity>0 0 0 0 -0 0</velocity>
          <acceleration>0 0 0 0 -0 0</acceleration>
          <wrench>0 0 0 0 -0 0</wrench>
        </link>
        <link name='rokae_link7'>
          <pose frame=''>0 0 1.41342 0 -0 0</pose>
          <velocity>0 0 0 0 -0 0</velocity>
          <acceleration>0 0 0 0 -0 0</acceleration>
          <wrench>0 0 0 0 -0 0</wrench>
        </link>
        <link name='taotong_link8'>
          <pose frame=''>0 0 1.66433 0 -0 0</pose>
          <velocity>0 0 0 0 -0 0</velocity>
          <acceleration>0 0 0 0 -0 0</acceleration>
          <wrench>0 0 0 0 -0 0</wrench>
        </link>
      </model>
      <light name='sun'>
        <pose frame=''>0 0 10 0 -0 0</pose>
      </light>
    </state>
    <gui fullscreen='0'>
      <camera name='user_camera'>
        <pose frame=''>1.03946 -5.76241 3.99242 0 0.543643 1.46819</pose>
        <view_controller>orbit</view_controller>
        <projection_type>perspective</projection_type>
      </camera>
    </gui>
    <model name='rokae'>
      <link name='rokae_base'>
        <pose frame=''>0 0 0 0 -0 0</pose>
        <inertial>
          <pose frame=''>-0.0183 0 0.067 0 -0 0</pose>
          <mass>5.48267</mass>
          <inertia>
            <ixx>0.056</ixx>
            <ixy>0</ixy>
            <ixz>0</ixz>
            <iyy>0.066</iyy>
            <iyz>0</iyz>
            <izz>0.035</izz>
          </inertia>
        </inertial>
        <collision name='rokae_base_collision'>
          <pose frame=''>0 0 0 0 -0 0</pose>
          <geometry>
            <mesh>
              <scale>0.001 0.001 0.001</scale>
              <uri>/home/hp/Desktop/rokae0717/src/rokae_description/meshes/collision/rokae_base.stl</uri>
            </mesh>
          </geometry>
          <surface>
            <contact>
              <ode/>
            </contact>
            <friction>
              <ode/>
              <torsional>
                <ode/>
              </torsional>
            </friction>
            <bounce/>
          </surface>
          <max_contacts>10</max_contacts>
        </collision>
        <visual name='rokae_base_visual'>
          <pose frame=''>0 0 0 0 -0 0</pose>
          <geometry>
            <mesh>
              <scale>0.001 0.001 0.001</scale>
              <uri>/home/hp/Desktop/rokae0717/src/rokae_description/meshes/visual/rokae_base.stl</uri>
            </mesh>
          </geometry>
          <material>
            <script>
              <name>Gazebo/Black</name>
              <uri>file://media/materials/scripts/gazebo.material</uri>
            </script>
          </material>
        </visual>
        <gravity>1</gravity>
        <velocity_decay/>
        <self_collide>0</self_collide>
        <enable_wind>0</enable_wind>
        <kinematic>0</kinematic>
      </link>
      <joint name='fixed' type='fixed'>
        <child>rokae_base</child>
        <parent>world</parent>
      </joint>
      <link name='rokae_link1'>
        <pose frame=''>0 0 0 0 -0 0</pose>
        <inertial>
          <pose frame=''>0 -0.017 0.32 0 -0 0</pose>
          <mass>5.96204</mass>
          <inertia>
            <ixx>0.051</ixx>
            <ixy>0</ixy>
            <ixz>0</ixz>
            <iyy>0.049</iyy>
            <iyz>-0.007</iyz>
            <izz>7.176</izz>
          </inertia>
        </inertial>
        <collision name='rokae_link1_collision'>
          <pose frame=''>0 0 0 0 -0 0</pose>
          <geometry>
            <mesh>
              <scale>0.001 0.001 0.001</scale>
              <uri>/home/hp/Desktop/rokae0717/src/rokae_description/meshes/collision/rokae_link1.stl</uri>
            </mesh>
          </geometry>
          <surface>
            <contact>
              <ode/>
            </contact>
            <friction>
              <ode/>
              <torsional>
                <ode/>
              </torsional>
            </friction>
            <bounce/>
          </surface>
          <max_contacts>10</max_contacts>
        </collision>
        <visual name='rokae_link1_visual'>
          <pose frame=''>0 0 0 0 -0 0</pose>
          <geometry>
            <mesh>
              <scale>0.001 0.001 0.001</scale>
              <uri>/home/hp/Desktop/rokae0717/src/rokae_description/meshes/visual/rokae_link1.stl</uri>
            </mesh>
          </geometry>
          <material>
            <script>
              <name>Gazebo/Black</name>
              <uri>file://media/materials/scripts/gazebo.material</uri>
            </script>
          </material>
        </visual>
        <gravity>1</gravity>
        <velocity_decay/>
        <self_collide>0</self_collide>
        <enable_wind>0</enable_wind>
        <kinematic>0</kinematic>
      </link>
      <joint name='xmate_joint_1' type='revolute'>
        <child>rokae_link1</child>
        <parent>rokae_base</parent>
        <axis>
          <xyz>0 0 1</xyz>
          <limit>
            <lower>-3.0527</lower>
            <upper>3.0527</upper>
            <effort>300</effort>
            <velocity>10</velocity>
          </limit>
          <dynamics>
            <spring_reference>0</spring_reference>
            <spring_stiffness>0</spring_stiffness>
          </dynamics>
          <use_parent_model_frame>1</use_parent_model_frame>
        </axis>
      </joint>
      <link name='rokae_link2'>
        <pose frame=''>0 0 0.404 0 -0 0</pose>
        <inertial>
          <pose frame=''>0 0.032 0.093 0 -0 0</pose>
          <mass>5.40302</mass>
          <inertia>
            <ixx>0.07</ixx>
            <ixy>0</ixy>
            <ixz>0</ixz>
            <iyy>7.23</iyy>
            <iyz>-0.014</iyz>
            <izz>0.011</izz>
          </inertia>
        </inertial>
        <collision name='rokae_link2_collision'>
          <pose frame=''>0 0 0 0 -0 0</pose>
          <geometry>
            <mesh>
              <scale>0.001 0.001 0.001</scale>
              <uri>/home/hp/Desktop/rokae0717/src/rokae_description/meshes/collision/rokae_link2.stl</uri>
            </mesh>
          </geometry>
          <surface>
            <contact>
              <ode/>
            </contact>
            <friction>
              <ode/>
              <torsional>
                <ode/>
              </torsional>
            </friction>
            <bounce/>
          </surface>
          <max_contacts>10</max_contacts>
        </collision>
        <visual name='rokae_link2_visual'>
          <pose frame=''>0 0 0 0 -0 0</pose>
          <geometry>
            <mesh>
              <scale>0.001 0.001 0.001</scale>
              <uri>/home/hp/Desktop/rokae0717/src/rokae_description/meshes/visual/rokae_link2.stl</uri>
            </mesh>
          </geometry>
          <material>
            <script>
              <name>Gazebo/Black</name>
              <uri>file://media/materials/scripts/gazebo.material</uri>
            </script>
          </material>
        </visual>
        <gravity>1</gravity>
        <velocity_decay/>
        <self_collide>0</self_collide>
        <enable_wind>0</enable_wind>
        <kinematic>0</kinematic>
      </link>
      <joint name='xmate_joint_2' type='revolute'>
        <child>rokae_link2</child>
        <parent>rokae_link1</parent>
        <axis>
          <xyz>0 1 0</xyz>
          <limit>
            <lower>-2.0933</lower>
            <upper>2.0933</upper>
            <effort>300</effort>
            <velocity>10</velocity>
          </limit>
          <dynamics>
            <spring_reference>0</spring_reference>
            <spring_stiffness>0</spring_stiffness>
          </dynamics>
          <use_parent_model_frame>1</use_parent_model_frame>
        </axis>
      </joint>
      <link name='rokae_link3'>
        <pose frame=''>0 0 0.641439 0 -0 0</pose>
        <inertial>
          <pose frame=''>0 -0.013 -0.067 0 -0 0</pose>
          <mass>3.95735</mass>
          <inertia>
            <ixx>0.022</ixx>
            <ixy>0</ixy>
            <ixz>0</ixz>
            <iyy>0.021</iyy>
            <iyz>-0.002</iyz>
            <izz>1.12</izz>
          </inertia>
        </inertial>
        <collision name='rokae_link3_collision'>
          <pose frame=''>0 0 0.1555 0 -0 0</pose>
          <geometry>
            <mesh>
              <scale>0.001 0.001 0.001</scale>
              <uri>/home/hp/Desktop/rokae0717/src/rokae_description/meshes/collision/rokae_link3.stl</uri>
            </mesh>
          </geometry>
          <surface>
            <contact>
              <ode/>
            </contact>
            <friction>
              <ode/>
              <torsional>
                <ode/>
              </torsional>
            </friction>
            <bounce/>
          </surface>
          <max_contacts>10</max_contacts>
        </collision>
        <visual name='rokae_link3_visual'>
          <pose frame=''>0 0 0.1555 0 -0 0</pose>
          <geometry>
            <mesh>
              <scale>0.001 0.001 0.001</scale>
              <uri>/home/hp/Desktop/rokae0717/src/rokae_description/meshes/visual/rokae_link3.stl</uri>
            </mesh>
          </geometry>
          <material>
            <script>
              <name>Gazebo/Black</name>
              <uri>file://media/materials/scripts/gazebo.material</uri>
            </script>
          </material>
        </visual>
        <gravity>1</gravity>
        <velocity_decay/>
        <self_collide>0</self_collide>
        <enable_wind>0</enable_wind>
        <kinematic>0</kinematic>
      </link>
      <joint name='xmate_joint_3' type='revolute'>
        <child>rokae_link3</child>
        <parent>rokae_link2</parent>
        <axis>
          <xyz>0 0 1</xyz>
          <limit>
            <lower>-3.0527</lower>
            <upper>3.0527</upper>
            <effort>300</effort>
            <velocity>10</velocity>
          </limit>
          <dynamics>
            <spring_reference>0</spring_reference>
            <spring_stiffness>0</spring_stiffness>
          </dynamics>
          <use_parent_model_frame>1</use_parent_model_frame>
        </axis>
      </joint>
      <link name='rokae_link4'>
        <pose frame=''>0 0 0.796938 0 -0 0</pose>
        <inertial>
          <pose frame=''>0 0.026 0.068 0 -0 0</pose>
          <mass>2.91217</mass>
          <inertia>
            <ixx>0.024</ixx>
            <ixy>0</ixy>
            <ixz>0</ixz>
            <iyy>1.138</iyy>
            <iyz>-0.004</iyz>
            <izz>0.005</izz>
          </inertia>
        </inertial>
        <collision name='rokae_link4_collision'>
          <pose frame=''>0 0 0 0 -0 0</pose>
          <geometry>
            <mesh>
              <scale>0.001 0.001 0.001</scale>
              <uri>/home/hp/Desktop/rokae0717/src/rokae_description/meshes/collision/rokae_link4.stl</uri>
            </mesh>
          </geometry>
          <surface>
            <contact>
              <ode/>
            </contact>
            <friction>
              <ode/>
              <torsional>
                <ode/>
              </torsional>
            </friction>
            <bounce/>
          </surface>
          <max_contacts>10</max_contacts>
        </collision>
        <visual name='rokae_link4_visual'>
          <pose frame=''>0 0 0 0 -0 0</pose>
          <geometry>
            <mesh>
              <scale>0.001 0.001 0.001</scale>
              <uri>/home/hp/Desktop/rokae0717/src/rokae_description/meshes/visual/rokae_link4.stl</uri>
            </mesh>
          </geometry>
          <material>
            <script>
              <name>Gazebo/Black</name>
              <uri>file://media/materials/scripts/gazebo.material</uri>
            </script>
          </material>
        </visual>
        <gravity>1</gravity>
        <velocity_decay/>
        <self_collide>0</self_collide>
        <enable_wind>0</enable_wind>
        <kinematic>0</kinematic>
      </link>
      <joint name='xmate_joint_4' type='revolute'>
        <child>rokae_link4</child>
        <parent>rokae_link3</parent>
        <axis>
          <xyz>0 1 0</xyz>
          <limit>
            <lower>-2.0933</lower>
            <upper>2.0933</upper>
            <effort>300</effort>
            <velocity>10</velocity>
          </limit>
          <dynamics>
            <spring_reference>0</spring_reference>
            <spring_stiffness>0</spring_stiffness>
          </dynamics>
          <use_parent_model_frame>1</use_parent_model_frame>
        </axis>
      </joint>
      <link name='rokae_link5'>
        <pose frame=''>0 0 1.01738 0 -0 0</pose>
        <inertial>
          <pose frame=''>0 -0.014 -0.079 0 -0 0</pose>
          <mass>2.47056</mass>
          <inertia>
            <ixx>0.019</ixx>
            <ixy>0</ixy>
            <ixz>0</ixz>
            <iyy>0.018</iyy>
            <iyz>-0.002</iyz>
            <izz>0.339</izz>
          </inertia>
        </inertial>
        <collision name='rokae_link5_collision'>
          <pose frame=''>0 0 0.145126 0 -0 0</pose>
          <geometry>
            <mesh>
              <scale>0.001 0.001 0.001</scale>
              <uri>/home/hp/Desktop/rokae0717/src/rokae_description/meshes/collision/rokae_link5.stl</uri>
            </mesh>
          </geometry>
          <surface>
            <contact>
              <ode/>
            </contact>
            <friction>
              <ode/>
              <torsional>
                <ode/>
              </torsional>
            </friction>
            <bounce/>
          </surface>
          <max_contacts>10</max_contacts>
        </collision>
        <visual name='rokae_link5_visual'>
          <pose frame=''>0 0 0.145126 0 -0 0</pose>
          <geometry>
            <mesh>
              <scale>0.001 0.001 0.001</scale>
              <uri>/home/hp/Desktop/rokae0717/src/rokae_description/meshes/visual/rokae_link5.stl</uri>
            </mesh>
          </geometry>
          <material>
            <script>
              <name>Gazebo/Black</name>
              <uri>file://media/materials/scripts/gazebo.material</uri>
            </script>
          </material>
        </visual>
        <gravity>1</gravity>
        <velocity_decay/>
        <self_collide>0</self_collide>
        <enable_wind>0</enable_wind>
        <kinematic>0</kinematic>
      </link>
      <joint name='xmate_joint_5' type='revolute'>
        <child>rokae_link5</child>
        <parent>rokae_link4</parent>
        <axis>
          <xyz>0 0 1</xyz>
          <limit>
            <lower>-3.0527</lower>
            <upper>3.0527</upper>
            <effort>300</effort>
            <velocity>10</velocity>
          </limit>
          <dynamics>
            <spring_reference>0</spring_reference>
            <spring_stiffness>0</spring_stiffness>
          </dynamics>
          <use_parent_model_frame>1</use_parent_model_frame>
        </axis>
      </joint>
      <link name='rokae_link6'>
        <pose frame=''>0 0 1.16251 0 -0 0</pose>
        <inertial>
          <pose frame=''>0 0.02 0.085 0 -0 0</pose>
          <mass>2.16053</mass>
          <inertia>
            <ixx>0.016</ixx>
            <ixy>0</ixy>
            <ixz>0</ixz>
            <iyy>0.351</iyy>
            <iyz>-0.003</iyz>
            <izz>0.003</izz>
          </inertia>
        </inertial>
        <collision name='rokae_link6_collision'>
          <pose frame=''>0 0 0 0 -0 0</pose>
          <geometry>
            <mesh>
              <scale>0.001 0.001 0.001</scale>
              <uri>/home/hp/Desktop/rokae0717/src/rokae_description/meshes/collision/rokae_link6.stl</uri>
            </mesh>
          </geometry>
          <surface>
            <contact>
              <ode/>
            </contact>
            <friction>
              <ode/>
              <torsional>
                <ode/>
              </torsional>
            </friction>
            <bounce/>
          </surface>
          <max_contacts>10</max_contacts>
        </collision>
        <visual name='rokae_link6_visual'>
          <pose frame=''>0 0 0 0 -0 0</pose>
          <geometry>
            <mesh>
              <scale>0.001 0.001 0.001</scale>
              <uri>/home/hp/Desktop/rokae0717/src/rokae_description/meshes/visual/rokae_link6.stl</uri>
            </mesh>
          </geometry>
          <material>
            <script>
              <name>Gazebo/Black</name>
              <uri>file://media/materials/scripts/gazebo.material</uri>
            </script>
          </material>
        </visual>
        <gravity>1</gravity>
        <velocity_decay/>
        <self_collide>0</self_collide>
        <enable_wind>0</enable_wind>
        <kinematic>0</kinematic>
      </link>
      <joint name='xmate_joint_6' type='revolute'>
        <child>rokae_link6</child>
        <parent>rokae_link5</parent>
        <axis>
          <xyz>0 1 0</xyz>
          <limit>
            <lower>-2.0933</lower>
            <upper>2.0933</upper>
            <effort>300</effort>
            <velocity>10</velocity>
          </limit>
          <dynamics>
            <spring_reference>0</spring_reference>
            <spring_stiffness>0</spring_stiffness>
          </dynamics>
          <use_parent_model_frame>1</use_parent_model_frame>
        </axis>
      </joint>
      <link name='rokae_link7'>
        <pose frame=''>0 0 1.41342 0 -0 0</pose>
        <inertial>
          <pose frame=''>0 0.012 -0.052 0 -0 0</pose>
          <mass>1.26834</mass>
          <inertia>
            <ixx>0.002</ixx>
            <ixy>-0</ixy>
            <ixz>-0</ixz>
            <iyy>0.001</iyy>
            <iyz>-0</iyz>
            <izz>0.337</izz>
          </inertia>
        </inertial>
        <collision name='rokae_link7_collision'>
          <pose frame=''>0 0 0 0 -0 0</pose>
          <geometry>
            <mesh>
              <scale>0.001 0.001 0.001</scale>
              <uri>/home/hp/Desktop/rokae0717/src/rokae_description/meshes/collision/rokae_link7.stl</uri>
            </mesh>
          </geometry>
          <surface>
            <contact>
              <ode/>
            </contact>
            <friction>
              <ode/>
              <torsional>
                <ode/>
              </torsional>
            </friction>
            <bounce/>
          </surface>
          <max_contacts>10</max_contacts>
        </collision>
        <visual name='rokae_link7_visual'>
          <pose frame=''>0 0 0 0 -0 0</pose>
          <geometry>
            <mesh>
              <scale>0.001 0.001 0.001</scale>
              <uri>/home/hp/Desktop/rokae0717/src/rokae_description/meshes/visual/rokae_link7.stl</uri>
            </mesh>
          </geometry>
          <material>
            <script>
              <name>Gazebo/Black</name>
              <uri>file://media/materials/scripts/gazebo.material</uri>
            </script>
          </material>
        </visual>
        <gravity>1</gravity>
        <velocity_decay/>
        <self_collide>0</self_collide>
        <enable_wind>0</enable_wind>
        <kinematic>0</kinematic>
      </link>
      <joint name='xmate_joint_7' type='revolute'>
        <child>rokae_link7</child>
        <parent>rokae_link6</parent>
        <axis>
          <xyz>0 0 1</xyz>
          <limit>
            <lower>-6.283</lower>
            <upper>6.283</upper>
            <effort>300</effort>
            <velocity>10</velocity>
          </limit>
          <dynamics>
            <spring_reference>0</spring_reference>
            <spring_stiffness>0</spring_stiffness>
          </dynamics>
          <use_parent_model_frame>1</use_parent_model_frame>
        </axis>
      </joint>
      <link name='taotong_link8'>
        <pose frame=''>0 0 1.66433 0 -0 0</pose>
        <inertial>
          <pose frame=''>0 0.012 -0.052 1.57 -0 0</pose>
          <mass>1.26834</mass>
          <inertia>
            <ixx>1.8</ixx>
            <ixy>9.4</ixy>
            <ixz>-2</ixz>
            <iyy>1.8</iyy>
            <iyz>-0</iyz>
            <izz>0.337</izz>
          </inertia>
        </inertial>
        <collision name='taotong_link8_collision'>
          <pose frame=''>0 0 0 1.57 -0 0</pose>
          <geometry>
            <mesh>
              <scale>3 3 3</scale>
              <uri>/home/hp/Desktop/rokae0717/src/rokae_description/meshes/taotong1_urdf.stl</uri>
            </mesh>
          </geometry>
          <surface>
            <contact>
              <ode/>
            </contact>
            <friction>
              <ode/>
              <torsional>
                <ode/>
              </torsional>
            </friction>
            <bounce/>
          </surface>
          <max_contacts>10</max_contacts>
        </collision>
        <visual name='taotong_link8_visual'>
          <pose frame=''>0 0 -0.25 1.57 -0 0</pose>
          <geometry>
            <mesh>
              <scale>3 3 3</scale>
              <uri>/home/hp/Desktop/rokae0717/src/rokae_description/meshes/taotong1_urdf.stl</uri>
            </mesh>
          </geometry>
          <material>
            <script>
              <name>Gazebo/Gray</name>
              <uri>file://media/materials/scripts/gazebo.material</uri>
            </script>
          </material>
        </visual>
        <gravity>1</gravity>
        <velocity_decay/>
        <self_collide>0</self_collide>
        <enable_wind>0</enable_wind>
        <kinematic>0</kinematic>
      </link>
      <joint name='xmate_joint_8' type='revolute'>
        <child>taotong_link8</child>
        <parent>rokae_link7</parent>
        <axis>
          <xyz>0 0 1</xyz>
          <limit>
            <lower>-6.283</lower>
            <upper>6.283</upper>
            <effort>300</effort>
            <velocity>10</velocity>
          </limit>
          <dynamics>
            <spring_reference>0</spring_reference>
            <spring_stiffness>0</spring_stiffness>
          </dynamics>
          <use_parent_model_frame>1</use_parent_model_frame>
        </axis>
      </joint>
      <static>0</static>
      <plugin name='gazebo_ros_control' filename='libgazebo_ros_control.so'>
        <robotNamespace>/rokae</robotNamespace>
        <robotSimType>gazebo_ros_control/DefaultRobotHWSim</robotSimType>
        <legacyModeNS>1</legacyModeNS>
      </plugin>
      <pose frame=''>0 0 0 0 -0 0</pose>
    </model>
    <model name='cafe_table'>
      <static>1</static>
      <link name='link'>
        <collision name='surface'>
          <pose frame=''>0 0 0.755 0 -0 0</pose>
          <geometry>
            <box>
              <size>0.913 0.913 0.04</size>
            </box>
          </geometry>
          <max_contacts>10</max_contacts>
          <surface>
            <contact>
              <ode/>
            </contact>
            <bounce/>
            <friction>
              <torsional>
                <ode/>
              </torsional>
              <ode/>
            </friction>
          </surface>
        </collision>
        <collision name='column'>
          <pose frame=''>0 0 0.37 0 -0 0</pose>
          <geometry>
            <box>
              <size>0.042 0.042 0.74</size>
            </box>
          </geometry>
          <max_contacts>10</max_contacts>
          <surface>
            <contact>
              <ode/>
            </contact>
            <bounce/>
            <friction>
              <torsional>
                <ode/>
              </torsional>
              <ode/>
            </friction>
          </surface>
        </collision>
        <collision name='base'>
          <pose frame=''>0 0 0.02 0 -0 0</pose>
          <geometry>
            <box>
              <size>0.56 0.56 0.04</size>
            </box>
          </geometry>
          <max_contacts>10</max_contacts>
          <surface>
            <contact>
              <ode/>
            </contact>
            <bounce/>
            <friction>
              <torsional>
                <ode/>
              </torsional>
              <ode/>
            </friction>
          </surface>
        </collision>
        <visual name='visual'>
          <geometry>
            <mesh>
              <uri>model://cafe_table/meshes/cafe_table.dae</uri>
            </mesh>
          </geometry>
        </visual>
        <self_collide>0</self_collide>
        <enable_wind>0</enable_wind>
        <kinematic>0</kinematic>
      </link>
      <pose frame=''>1.12129 -0.113215 0 0 -0 0</pose>
    </model>
    <model name='kinect'>
      <pose frame=''>1.26896 0.626159 0.036 0 -0 0</pose>
      <link name='link'>
        <inertial>
          <mass>0.1</mass>
          <inertia>
            <ixx>1</ixx>
            <ixy>0</ixy>
            <ixz>0</ixz>
            <iyy>1</iyy>
            <iyz>0</iyz>
            <izz>1</izz>
          </inertia>
        </inertial>
        <collision name='collision'>
          <geometry>
            <box>
              <size>0.073 0.276 0.072</size>
            </box>
          </geometry>
          <max_contacts>10</max_contacts>
          <surface>
            <contact>
              <ode/>
            </contact>
            <bounce/>
            <friction>
              <torsional>
                <ode/>
              </torsional>
              <ode/>
            </friction>
          </surface>
        </collision>
        <visual name='visual'>
          <geometry>
            <mesh>
              <uri>model://kinect/meshes/kinect.dae</uri>
            </mesh>
          </geometry>
        </visual>
        <sensor name='camera' type='depth'>
          <update_rate>20</update_rate>
          <camera name='__default__'>
            <horizontal_fov>1.0472</horizontal_fov>
            <image>
              <width>640</width>
              <height>480</height>
              <format>R8G8B8</format>
            </image>
            <clip>
              <near>0.05</near>
              <far>3</far>
            </clip>
          </camera>
        </sensor>
        <self_collide>0</self_collide>
        <enable_wind>0</enable_wind>
        <kinematic>0</kinematic>
      </link>
    </model>
  </world>
</sdf>
