<?xml version="1.0" encoding="utf-8"?>
<!-- This URDF was automatically created by SolidWorks to URDF Exporter! Originally created by Stephen Brawner (brawner@gmail.com) 
     Commit Version: 1.5.1-0-g916b5db  Build Version: 1.5.7152.31018
     For more information, please see http://wiki.ros.org/sw_urdf_exporter -->
<robot
  name="hole_battery_describe">
  <link    name="hole_base_link"   xmlns:xacro="http://www.ros.org/wiki/xacro">

    <inertial>
      <origin
        xyz="-0.18358 0.00059075 -0.19041"
        rpy="0 0 0" />
      <mass
        value="2.0722" />
      <inertia
        ixx="0.040611"
        ixy="-0.00037803"
        ixz="-0.0028159"
        iyy="0.083995"
        iyz="-0.00066456"
        izz="0.043726" />
    </inertial>
    <visual>
      <origin
        xyz="0 0 0"
        rpy="0 0 0" />
      <geometry>
        <mesh
          filename="package://battery_pack_describe/meshes/hole_base_link.dae" />
      </geometry>
      <material
        name="">
        <color
          rgba="0.79216 0.81961 0.93333 1" />
      </material>
    </visual>
    <collision>
      <origin
        xyz="0 0 0"
        rpy="0 0 0" />
      <geometry>
        <box size="0.5 0.5 0.05" />
        <mesh
          filename="package://battery_pack_describe/meshes/hole_base_link.dae" />
      </geometry>
    </collision>
  </link>

  <gazebo reference="hole_base_link">
    <!-- <material>Gazebo/FlatBlack</material> -->
      <maxVel>0.01</maxVel>
      <kd>1</kd>
      <maxContacts>20</maxContacts>
      <mu2>50000</mu2>
      <selfCollide>0</selfCollide>
      <mu1>50000</mu1>
      <minDepth>0</minDepth>
      <kp>1000000000000.0</kp>
  </gazebo>


  <link
    name="hole_bolt_Link">
    <inertial>
      <origin
        xyz="-0.0222479735541268 -2.42669320749123E-09 1.13997719250469E-09"
        rpy="0 0 0" />
      <mass
        value="0.010043058879212" />
      <inertia
        ixx="8.16036465000949E-08"
        ixy="-2.67875420869616E-13"
        ixz="1.25078148415981E-13"
        iyy="1.22914699774063E-06"
        iyz="5.98228908164556E-14"
        izz="1.22914675774153E-06" />
    </inertial>
    <visual>
      <origin
        xyz="0 0 0"
        rpy="0 0 0" />
      <geometry>
        <mesh
          filename="package://battery_pack_describe/meshes/hole_bolt_Link.STL" />
      </geometry>
      <material
        name="">
        <color
          rgba="0.776470588235294 0.756862745098039 0.737254901960784 1" />
      </material>
    </visual>
    <collision>
      <origin
        xyz="0 0 0"
        rpy="0 0 0" />
      <geometry>
        <cylinder length="0.04" radius="0.02"/>

        <mesh
          filename="package://battery_pack_describe/meshes/hole_bolt_Link.STL" />
      </geometry>
    </collision>
  </link>
  <gazebo reference="hole_bolt_Link">
      <maxVel>0.01</maxVel>
      <kd>1</kd>
      <maxContacts>20</maxContacts>
      <mu2>50000</mu2>
      <selfCollide>0</selfCollide>
      <mu1>50000</mu1>
      <minDepth>0</minDepth>
      <kp>1000000000000.0</kp>
    <material>Gazebo/Grey </material>
  </gazebo>


  <joint
    name="hole_bolt_joint"
    type="continuous">
    <origin
      xyz="0.025323 0.063548 0.025"
      rpy="2.7498 0 3.1416" />
    <parent
      link="hole_base_link" />
    <child
      link="hole_bolt_Link" />
    <axis
      xyz="1 0 0" />
  </joint>
  <link
    name="hole_nut_Link">
    <inertial>
      <origin
        xyz="-8.23260334903431E-10 -3.46944695195361E-18 0.00260060243313041"
        rpy="0 0 0" />
      <mass
        value="0.00265736664598247" />
      <inertia
        ixx="2.79753045005072E-08"
        ixy="1.55317024420596E-23"
        ixz="-1.31796668969802E-18"
        iyy="2.79771327058771E-08"
        iyz="-4.83267733690945E-14"
        izz="4.46160415460722E-08" />
    </inertial>
    <visual>
      <origin
        xyz="0 0 0"
        rpy="0 0 0" />
      <geometry>
        <mesh
          filename="package://battery_pack_describe/meshes/hole_nut_Link.STL" />
      </geometry>
      <material
        name="">
        <color
          rgba="0.776470588235294 0.756862745098039 0.737254901960784 1" />
      </material>
    </visual>
    <collision>
      <origin
        xyz="0 0 0"
        rpy="0 0 0" />
      <geometry>
        <mesh
          filename="package://battery_pack_describe/meshes/hole_nut_Link.STL" />
      </geometry>
    </collision>
  </link>
      <gazebo reference="hole_nut_Link">
    <material>Gazebo/Gray</material>
  </gazebo>


  <joint
    name="hole_nut_joint"
    type="fixed">
    <origin
      xyz="0.035123 0.063548 0.025"
      rpy="-1.5708 0 -1.5708" />
    <parent
      link="hole_base_link" />
    <child
      link="hole_nut_Link" />
    <axis
      xyz="0 0 -1" />
  </joint>
</robot>