<?xml version="1.0" encoding="utf-8"?>
<!-- This URDF was automatically created by SolidWorks to URDF Exporter! Originally created by Stephen Brawner (brawner@gmail.com) 
     Commit Version: 1.5.1-0-g916b5db  Build Version: 1.5.7152.31018
     For more information, please see http://wiki.ros.org/sw_urdf_exporter -->
<robot name="v_battery">
  <link name="v_battery_base_link"
    xmlns:xacro="http://www.ros.org/wiki/xacro">
    <inertial>
      <origin xyz="-0.17823 0.0014541 -0.18254" rpy="0 0 0" />
      <mass value="2.1452" />
      <inertia ixx="0.04437" ixy="-0.00066651" ixz="-0.0054047" iyy="0.089539" iyz="-0.0010719" izz="0.045613" />
    </inertial>
    <visual>
      <origin xyz="0 0 0" rpy="0 0 0" />
      <geometry>
        <mesh filename="package://battery_pack_describe/meshes/v_battery_base_link.dae" />
      </geometry>
      <material name="">
        <color rgba="0.79216 0.81961 0.93333 1" />
      </material>
    </visual>
    <collision>
      <origin xyz="0 0 0" rpy="0 0 0" />
      <geometry>
        <!-- <box size="0.5 0.5 0.05" /> -->
        <mesh filename="package://battery_pack_describe/meshes/v_battery_base_link.dae" />
      </geometry>
    </collision>
  </link>

  <gazebo reference="v_battery_base_link">
    <!-- <material>Gazebo/GreyTransparent</material> -->
    <kp>1000000.0</kp>
    <kd>100.0</kd>
    <mu1>50000000000000000000.0</mu1>
    <mu2>50000000000000000000.0</mu2>
    <maxVel>0</maxVel>
    <minDepth>0.001</minDepth>
    <fdir1>1 0 0</fdir1>

  </gazebo>

  <!-- <gazebo reference="v_battery_base_link">
      <maxVel>100</maxVel>
      <kd>200</kd>
      <maxContacts>200</maxContacts>
      <mu2>50000000000000000000</mu2>
      <selfCollide>10</selfCollide>
      <mu1>50000000000000000000</mu1>
      <minDepth>10</minDepth>
      <kp>1000000000000.0</kp> -->


  <!-- <gravity>bool</gravity> -->

  <!-- <gravity>bool</gravity> -->
  <!-- <maxVel>100</maxVel>
      <kd>10</kd>
      <maxContacts>200</maxContacts>
      <mu2>10</mu2>
      <selfCollide>10</selfCollide>
      <mu1>10</mu1>
      <minDepth>10</minDepth>
      <kp>1</kp> -->

  <!-- </gazebo>  -->


  <link name="v_battery_bolt_Link">
    <inertial>
      <origin xyz="-0.00224797355412683 -2.42669320749123E-09 1.13997717515746E-09" rpy="0 0 0" />
      <mass value="0.010043058879212" />
      <inertia ixx="8.16036465000949E-08" ixy="-2.67875420699996E-13" ixz="1.25078148224805E-13" iyy="1.22914699774063E-06" iyz="5.9822890763516E-14" izz="1.22914675774153E-06" />
    </inertial>
    <visual>
      <origin xyz="0 0 0" rpy="0 0 0" />
      <geometry>
        <mesh filename="package://battery_pack_describe/meshes/v_battery_bolt_Link_metal.dae" />
      </geometry>
      <material name="">
        <color rgba="0.776470588235294 0.756862745098039 0.737254901960784 1" />
      </material>
    </visual>
    <collision>
      <origin xyz="0 0 0" rpy="0 0 0" />
      <geometry>
        <!-- <cylinder length="0.002" radius="0.002"/> -->
        <mesh filename="package://battery_pack_describe/meshes/v_battery_bolt_Link_metal.dae" />
      </geometry>
    </collision>
  </link>


  <!--摩擦力参考链接，我修改了mu的大小。 https://boschresearch.github.io/pcg_gazebo_pkgs/tutorials/parsers/urdf/robots/ 
https://whtqh.gitbooks.io/gazebo_simu_chs/content/using_a_urdf_model.html  摩擦力和其他参数，定义链接
-->
  <gazebo reference="v_battery_bolt_Link">
    <maxVel>0.01</maxVel>
    <kd>1</kd>
    <maxContacts>20</maxContacts>
    <mu2>5000000000000000</mu2>
    <selfCollide>0</selfCollide>
    <mu1>5000000000000000</mu1>
    <minDepth>0</minDepth>
    <kp>1000000000000.0</kp>
    <material>Gazebo/Grey </material>
  </gazebo>





  <joint name="v_battery_bolt_joint" type="continuous">
    <origin xyz="0.057323 -0.038452 0" rpy="0.39309 1.5708 0" />
    <parent link="v_battery_base_link" />
    <child link="v_battery_bolt_Link" />
    <axis xyz="1 0 0" />
  </joint>
  <link name="v_battery_nut_Link">
    <inertial>
      <origin xyz="-8.23260362659006E-10 1.38777878078145E-17 -0.0026006024331304" rpy="0 0 0" />
      <mass value="0.00265736664598247" />
      <inertia ixx="2.79753045005072E-08" ixy="5.04580173657347E-23" ixz="1.31793951411467E-18" iyy="2.79771327058771E-08" iyz="-4.83267733699208E-14" izz="4.46160415460721E-08" />
    </inertial>
    <visual>
      <origin xyz="0 0 0" rpy="0 0 0" />
      <geometry>
        <mesh filename="package://battery_pack_describe/meshes/v_battery_nut_Link.dae" />
      </geometry>
      <material name="">
        <color rgba="0.776470588235294 0.756862745098039 0.737254901960784 1" />
      </material>
    </visual>
    <collision>
      <origin xyz="0 0 0" rpy="0 0 0" />
      <geometry>
        <!-- <cylinder length="0.001" radius="0.02"/> -->
        <mesh filename="package://battery_pack_describe/meshes/v_battery_nut_Link.dae" />
      </geometry>
    </collision>
  </link>

  <!-- <gazebo reference="v_battery_nut_Link">
    <mu1>0.1</mu1>
    <mu2>0.1</mu2>
    <kp>1</kp>
    <kd>10.0</kd>
    <minDepth>0.001</minDepth>
    <maxVel>0.1</maxVel>
    <fdir1>1 0 0</fdir1>
    <material>Gazebo/FlatBlack</material>
  </gazebo> -->


  <joint name="v_battery_nut_joint" type="fixed">
    <origin xyz="0.057323 -0.038452 0" rpy="0 0 2.7485" />
    <parent link="v_battery_base_link" />
    <child link="v_battery_nut_Link" />
    <axis xyz="0 0 -1" />
  </joint>
</robot>